2023-12-01 13:53:07,484 - ERROR - Error desconocido con la ip 10.224.126.89
2023-12-01 13:53:07,484 - ERROR - Error: 1054 (42S22): Unknown column 'status' in 'field list'
2023-12-01 13:53:07,485 - ERROR - TRAZABILIDAD: Traceback (most recent call last):
  File "/home/donkami/.local/lib/python3.10/site-packages/mysql/connector/connection_cext.py", line 611, in cmd_query
    self._cmysql.query(
_mysql_connector.MySQLInterfaceError: Unknown column 'status' in 'field list'

The above exception was the direct cause of the following exception:

Traceback (most recent call last):
  File "/home/donkami/Sona/devnet-candelaria/Services/Wan/main.py", line 105, in get_uptime
    save_bd(data_wan)
  File "/home/donkami/Sona/devnet-candelaria/Services/Wan/main.py", line 223, in save_bd
    cursor.execute(query + values)
  File "/home/donkami/.local/lib/python3.10/site-packages/mysql/connector/cursor_cext.py", line 330, in execute
    result = self._cnx.cmd_query(
  File "/home/donkami/.local/lib/python3.10/site-packages/mysql/connector/connection_cext.py", line 619, in cmd_query
    raise get_mysql_exception(
mysql.connector.errors.ProgrammingError: 1054 (42S22): Unknown column 'status' in 'field list'

