2024-06-07 11:55:09,872 - ERROR - Error al conectarse a la base de datos
2024-06-07 11:55:09,872 - ERROR - Error al conectarse a la base de datos
Error al conectarse a la base de datos
2024-06-07 11:55:09,872 - ERROR - Traceback (most recent call last):
  File "/home/donkami/.local/lib/python3.10/site-packages/mysql/connector/connection_cext.py", line 291, in _open_connection
    self._cmysql.connect(**cnx_kwargs)
_mysql_connector.MySQLInterfaceError: Can't connect to MySQL server on '127.0.0.1:3306' (111)

The above exception was the direct cause of the following exception:

Traceback (most recent call last):
  File "/home/donkami/Sona/devnet-candelaria/Services/FiM/save_register.py", line 24, in database_connection
    mydb = mysql.connector.connect(
  File "/home/donkami/.local/lib/python3.10/site-packages/mysql/connector/pooling.py", line 293, in connect
    return CMySQLConnection(*args, **kwargs)
  File "/home/donkami/.local/lib/python3.10/site-packages/mysql/connector/connection_cext.py", line 120, in __init__
    self.connect(**kwargs)
  File "/home/donkami/.local/lib/python3.10/site-packages/mysql/connector/abstracts.py", line 1181, in connect
    self._open_connection()
  File "/home/donkami/.local/lib/python3.10/site-packages/mysql/connector/connection_cext.py", line 296, in _open_connection
    raise get_mysql_exception(
mysql.connector.errors.DatabaseError: 2003 (HY000): Can't connect to MySQL server on '127.0.0.1:3306' (111)

2024-06-07 11:55:09,872 - ERROR - Traceback (most recent call last):
  File "/home/donkami/.local/lib/python3.10/site-packages/mysql/connector/connection_cext.py", line 291, in _open_connection
    self._cmysql.connect(**cnx_kwargs)
_mysql_connector.MySQLInterfaceError: Can't connect to MySQL server on '127.0.0.1:3306' (111)

The above exception was the direct cause of the following exception:

Traceback (most recent call last):
  File "/home/donkami/Sona/devnet-candelaria/Services/FiM/save_register.py", line 24, in database_connection
    mydb = mysql.connector.connect(
  File "/home/donkami/.local/lib/python3.10/site-packages/mysql/connector/pooling.py", line 293, in connect
    return CMySQLConnection(*args, **kwargs)
  File "/home/donkami/.local/lib/python3.10/site-packages/mysql/connector/connection_cext.py", line 120, in __init__
    self.connect(**kwargs)
  File "/home/donkami/.local/lib/python3.10/site-packages/mysql/connector/abstracts.py", line 1181, in connect
    self._open_connection()
  File "/home/donkami/.local/lib/python3.10/site-packages/mysql/connector/connection_cext.py", line 296, in _open_connection
    raise get_mysql_exception(
mysql.connector.errors.DatabaseError: 2003 (HY000): Can't connect to MySQL server on '127.0.0.1:3306' (111)

Traceback (most recent call last):
  File "/home/donkami/.local/lib/python3.10/site-packages/mysql/connector/connection_cext.py", line 291, in _open_connection
    self._cmysql.connect(**cnx_kwargs)
_mysql_connector.MySQLInterfaceError: Can't connect to MySQL server on '127.0.0.1:3306' (111)

The above exception was the direct cause of the following exception:

Traceback (most recent call last):
  File "/home/donkami/Sona/devnet-candelaria/Services/FiM/save_register.py", line 24, in database_connection
    mydb = mysql.connector.connect(
  File "/home/donkami/.local/lib/python3.10/site-packages/mysql/connector/pooling.py", line 293, in connect
    return CMySQLConnection(*args, **kwargs)
  File "/home/donkami/.local/lib/python3.10/site-packages/mysql/connector/connection_cext.py", line 120, in __init__
    self.connect(**kwargs)
  File "/home/donkami/.local/lib/python3.10/site-packages/mysql/connector/abstracts.py", line 1181, in connect
    self._open_connection()
  File "/home/donkami/.local/lib/python3.10/site-packages/mysql/connector/connection_cext.py", line 296, in _open_connection
    raise get_mysql_exception(
mysql.connector.errors.DatabaseError: 2003 (HY000): Can't connect to MySQL server on '127.0.0.1:3306' (111)

2024-06-07 11:55:09,873 - ERROR - 2003 (HY000): Can't connect to MySQL server on '127.0.0.1:3306' (111)
2024-06-07 11:55:09,873 - ERROR - 2003 (HY000): Can't connect to MySQL server on '127.0.0.1:3306' (111)
2003 (HY000): Can't connect to MySQL server on '127.0.0.1:3306' (111)
2024-06-07 11:55:09,873 - ERROR - Error en la funcion principal - Base RAP11
2024-06-07 11:55:09,873 - ERROR - Error en la funcion principal - Base RAP11
Error en la funcion principal - Base RAP11
2024-06-07 11:55:09,873 - ERROR - Traceback (most recent call last):
  File "/home/donkami/Sona/devnet-candelaria/Services/FiM/main.py", line 57, in check_fim
    update_status_base(base)
  File "/home/donkami/Sona/devnet-candelaria/Services/FiM/save_register.py", line 66, in update_status_base
    cursor = mydb.cursor()
AttributeError: 'NoneType' object has no attribute 'cursor'

2024-06-07 11:55:09,873 - ERROR - Traceback (most recent call last):
  File "/home/donkami/Sona/devnet-candelaria/Services/FiM/main.py", line 57, in check_fim
    update_status_base(base)
  File "/home/donkami/Sona/devnet-candelaria/Services/FiM/save_register.py", line 66, in update_status_base
    cursor = mydb.cursor()
AttributeError: 'NoneType' object has no attribute 'cursor'

Traceback (most recent call last):
  File "/home/donkami/Sona/devnet-candelaria/Services/FiM/main.py", line 57, in check_fim
    update_status_base(base)
  File "/home/donkami/Sona/devnet-candelaria/Services/FiM/save_register.py", line 66, in update_status_base
    cursor = mydb.cursor()
AttributeError: 'NoneType' object has no attribute 'cursor'

2024-06-07 11:55:09,873 - ERROR - 'NoneType' object has no attribute 'cursor'
2024-06-07 11:55:09,873 - ERROR - 'NoneType' object has no attribute 'cursor'
'NoneType' object has no attribute 'cursor'
