2024-09-13 19:07:40,163 - ERROR - Traceback (most recent call last):
  File "/home/donkami/.local/lib/python3.10/site-packages/mysql/connector/connection_cext.py", line 291, in _open_connection
    self._cmysql.connect(**cnx_kwargs)
_mysql_connector.MySQLInterfaceError: Access denied for user 'donkami'@'172.18.0.1' (using password: NO)

The above exception was the direct cause of the following exception:

Traceback (most recent call last):
  File "/home/donkami/Sona/devnet-candelaria/Services/Docker_Monitoring/db_connections.py", line 29, in devnet_connection
    db_connector = mysql.connector.connect(
  File "/home/donkami/.local/lib/python3.10/site-packages/mysql/connector/pooling.py", line 293, in connect
    return CMySQLConnection(*args, **kwargs)
  File "/home/donkami/.local/lib/python3.10/site-packages/mysql/connector/connection_cext.py", line 120, in __init__
    self.connect(**kwargs)
  File "/home/donkami/.local/lib/python3.10/site-packages/mysql/connector/abstracts.py", line 1181, in connect
    self._open_connection()
  File "/home/donkami/.local/lib/python3.10/site-packages/mysql/connector/connection_cext.py", line 296, in _open_connection
    raise get_mysql_exception(
mysql.connector.errors.ProgrammingError: 1045 (28000): Access denied for user 'donkami'@'172.18.0.1' (using password: NO)

2024-09-13 19:07:40,164 - ERROR - Error en la función `devnet_connection` en el archivo `db_connections`
2024-09-13 19:07:40,164 - ERROR - 1045 (28000): Access denied for user 'donkami'@'172.18.0.1' (using password: NO)
2024-09-13 19:07:40,164 - ERROR - Traceback (most recent call last):
  File "/home/donkami/Sona/devnet-candelaria/Services/Docker_Monitoring/db_update_devnet.py", line 58, in update_devnet_data
    devnet_cursor = db_connector.cursor()
AttributeError: 'NoneType' object has no attribute 'cursor'

2024-09-13 19:07:40,164 - ERROR - 'NoneType' object has no attribute 'cursor'
2024-09-13 19:07:40,164 - ERROR - Error en la función `update_devnet_data` en el archivo `db_update_devnet`
2024-09-13 19:07:40,167 - ERROR - Traceback (most recent call last):
  File "/home/donkami/Sona/devnet-candelaria/Services/Docker_Monitoring/db_update_devnet.py", line 58, in update_devnet_data
    devnet_cursor = db_connector.cursor()
AttributeError: 'NoneType' object has no attribute 'cursor'

During handling of the above exception, another exception occurred:

Traceback (most recent call last):
  File "/home/donkami/.local/lib/python3.10/site-packages/mysql/connector/connection_cext.py", line 291, in _open_connection
    self._cmysql.connect(**cnx_kwargs)
_mysql_connector.MySQLInterfaceError: Access denied for user 'donkami'@'172.18.0.1' (using password: NO)

The above exception was the direct cause of the following exception:

Traceback (most recent call last):
  File "/home/donkami/Sona/devnet-candelaria/Services/Docker_Monitoring/db_connections.py", line 29, in devnet_connection
    db_connector = mysql.connector.connect(
  File "/home/donkami/.local/lib/python3.10/site-packages/mysql/connector/pooling.py", line 293, in connect
    return CMySQLConnection(*args, **kwargs)
  File "/home/donkami/.local/lib/python3.10/site-packages/mysql/connector/connection_cext.py", line 120, in __init__
    self.connect(**kwargs)
  File "/home/donkami/.local/lib/python3.10/site-packages/mysql/connector/abstracts.py", line 1181, in connect
    self._open_connection()
  File "/home/donkami/.local/lib/python3.10/site-packages/mysql/connector/connection_cext.py", line 296, in _open_connection
    raise get_mysql_exception(
mysql.connector.errors.ProgrammingError: 1045 (28000): Access denied for user 'donkami'@'172.18.0.1' (using password: NO)

2024-09-13 19:07:40,167 - ERROR - Error en la función `devnet_connection` en el archivo `db_connections`
2024-09-13 19:07:40,167 - ERROR - 1045 (28000): Access denied for user 'donkami'@'172.18.0.1' (using password: NO)
2024-09-13 19:07:40,167 - ERROR - Traceback (most recent call last):
  File "/home/donkami/Sona/devnet-candelaria/Services/Docker_Monitoring/db_update_devnet.py", line 58, in update_devnet_data
    devnet_cursor = db_connector.cursor()
AttributeError: 'NoneType' object has no attribute 'cursor'

During handling of the above exception, another exception occurred:

Traceback (most recent call last):
  File "/home/donkami/Sona/devnet-candelaria/Services/Docker_Monitoring/db_update_devnet.py", line 115, in datetime_register
    devnet_cursor = db_connector.cursor()
AttributeError: 'NoneType' object has no attribute 'cursor'

2024-09-13 19:07:40,168 - ERROR - Error en la función `datetime_register` en el archivo `db_update_devnet`
2024-09-13 19:07:40,168 - ERROR - 'NoneType' object has no attribute 'cursor'
2024-09-13 19:07:40,171 - ERROR - Traceback (most recent call last):
  File "/home/donkami/.local/lib/python3.10/site-packages/mysql/connector/connection_cext.py", line 291, in _open_connection
    self._cmysql.connect(**cnx_kwargs)
_mysql_connector.MySQLInterfaceError: Access denied for user 'donkami'@'172.18.0.1' (using password: NO)

The above exception was the direct cause of the following exception:

Traceback (most recent call last):
  File "/home/donkami/Sona/devnet-candelaria/Services/Docker_Monitoring/db_connections.py", line 29, in devnet_connection
    db_connector = mysql.connector.connect(
  File "/home/donkami/.local/lib/python3.10/site-packages/mysql/connector/pooling.py", line 293, in connect
    return CMySQLConnection(*args, **kwargs)
  File "/home/donkami/.local/lib/python3.10/site-packages/mysql/connector/connection_cext.py", line 120, in __init__
    self.connect(**kwargs)
  File "/home/donkami/.local/lib/python3.10/site-packages/mysql/connector/abstracts.py", line 1181, in connect
    self._open_connection()
  File "/home/donkami/.local/lib/python3.10/site-packages/mysql/connector/connection_cext.py", line 296, in _open_connection
    raise get_mysql_exception(
mysql.connector.errors.ProgrammingError: 1045 (28000): Access denied for user 'donkami'@'172.18.0.1' (using password: NO)

2024-09-13 19:07:40,171 - ERROR - Error en la función `devnet_connection` en el archivo `db_connections`
2024-09-13 19:07:40,171 - ERROR - 1045 (28000): Access denied for user 'donkami'@'172.18.0.1' (using password: NO)
2024-09-13 19:07:40,171 - ERROR - Traceback (most recent call last):
  File "/home/donkami/Sona/devnet-candelaria/Services/Docker_Monitoring/db_update_devnet.py", line 115, in datetime_register
    devnet_cursor = db_connector.cursor()
AttributeError: 'NoneType' object has no attribute 'cursor'

2024-09-13 19:07:40,171 - ERROR - Error en la función `datetime_register` en el archivo `db_update_devnet`
2024-09-13 19:07:40,171 - ERROR - 'NoneType' object has no attribute 'cursor'
2024-09-13 19:08:59,091 - ERROR - Traceback (most recent call last):
  File "/home/donkami/Sona/devnet-candelaria/Services/Docker_Monitoring/db_update_devnet.py", line 62, in update_devnet_data
    devnet_cursor.executemany(query, data_tuple)
  File "/home/donkami/.local/lib/python3.10/site-packages/mysql/connector/cursor_cext.py", line 465, in executemany
    self.execute(operation, params)
  File "/home/donkami/.local/lib/python3.10/site-packages/mysql/connector/cursor_cext.py", line 323, in execute
    stmt = RE_PY_PARAM.sub(psub, stmt)
  File "/home/donkami/.local/lib/python3.10/site-packages/mysql/connector/cursor_cext.py", line 112, in __call__
    raise ProgrammingError(
mysql.connector.errors.ProgrammingError: Not enough parameters for the SQL statement

2024-09-13 19:08:59,091 - ERROR - Not enough parameters for the SQL statement
2024-09-13 19:08:59,091 - ERROR - Error en la función `update_devnet_data` en el archivo `db_update_devnet`
2024-09-13 19:09:37,783 - ERROR - Traceback (most recent call last):
  File "/home/donkami/Sona/devnet-candelaria/Services/Docker_Monitoring/db_update_devnet.py", line 62, in update_devnet_data
    devnet_cursor.executemany(query, data_tuple)
  File "/home/donkami/.local/lib/python3.10/site-packages/mysql/connector/cursor_cext.py", line 465, in executemany
    self.execute(operation, params)
  File "/home/donkami/.local/lib/python3.10/site-packages/mysql/connector/cursor_cext.py", line 323, in execute
    stmt = RE_PY_PARAM.sub(psub, stmt)
  File "/home/donkami/.local/lib/python3.10/site-packages/mysql/connector/cursor_cext.py", line 112, in __call__
    raise ProgrammingError(
mysql.connector.errors.ProgrammingError: Not enough parameters for the SQL statement

2024-09-13 19:09:37,783 - ERROR - Not enough parameters for the SQL statement
2024-09-13 19:09:37,783 - ERROR - Error en la función `update_devnet_data` en el archivo `db_update_devnet`
2024-09-13 19:10:54,797 - ERROR - Traceback (most recent call last):
  File "/home/donkami/.local/lib/python3.10/site-packages/mysql/connector/connection_cext.py", line 611, in cmd_query
    self._cmysql.query(
_mysql_connector.MySQLInterfaceError: You have an error in your SQL syntax; check the manual that corresponds to your MySQL server version for the right syntax to use near 'INSER INTO `dcs`.`docker_containers` 
        (name,
        status,
        cpu' at line 1

The above exception was the direct cause of the following exception:

Traceback (most recent call last):
  File "/home/donkami/Sona/devnet-candelaria/Services/Docker_Monitoring/db_update_devnet.py", line 62, in update_devnet_data
    devnet_cursor.executemany(query, data_tuple)
  File "/home/donkami/.local/lib/python3.10/site-packages/mysql/connector/cursor_cext.py", line 465, in executemany
    self.execute(operation, params)
  File "/home/donkami/.local/lib/python3.10/site-packages/mysql/connector/cursor_cext.py", line 330, in execute
    result = self._cnx.cmd_query(
  File "/home/donkami/.local/lib/python3.10/site-packages/mysql/connector/connection_cext.py", line 619, in cmd_query
    raise get_mysql_exception(
mysql.connector.errors.ProgrammingError: 1064 (42000): You have an error in your SQL syntax; check the manual that corresponds to your MySQL server version for the right syntax to use near 'INSER INTO `dcs`.`docker_containers` 
        (name,
        status,
        cpu' at line 1

2024-09-13 19:10:54,798 - ERROR - 1064 (42000): You have an error in your SQL syntax; check the manual that corresponds to your MySQL server version for the right syntax to use near 'INSER INTO `dcs`.`docker_containers` 
        (name,
        status,
        cpu' at line 1
2024-09-13 19:10:54,798 - ERROR - Error en la función `update_devnet_data` en el archivo `db_update_devnet`
2024-09-13 19:11:35,180 - ERROR - Traceback (most recent call last):
  File "/home/donkami/.local/lib/python3.10/site-packages/mysql/connector/connection_cext.py", line 611, in cmd_query
    self._cmysql.query(
_mysql_connector.MySQLInterfaceError: You have an error in your SQL syntax; check the manual that corresponds to your MySQL server version for the right syntax to use near 'INSER INTO `dcs`.`docker_containers` 
        (`name`,
        `status`,
       ' at line 1

The above exception was the direct cause of the following exception:

Traceback (most recent call last):
  File "/home/donkami/Sona/devnet-candelaria/Services/Docker_Monitoring/db_update_devnet.py", line 62, in update_devnet_data
    devnet_cursor.executemany(query, data_tuple)
  File "/home/donkami/.local/lib/python3.10/site-packages/mysql/connector/cursor_cext.py", line 465, in executemany
    self.execute(operation, params)
  File "/home/donkami/.local/lib/python3.10/site-packages/mysql/connector/cursor_cext.py", line 330, in execute
    result = self._cnx.cmd_query(
  File "/home/donkami/.local/lib/python3.10/site-packages/mysql/connector/connection_cext.py", line 619, in cmd_query
    raise get_mysql_exception(
mysql.connector.errors.ProgrammingError: 1064 (42000): You have an error in your SQL syntax; check the manual that corresponds to your MySQL server version for the right syntax to use near 'INSER INTO `dcs`.`docker_containers` 
        (`name`,
        `status`,
       ' at line 1

2024-09-13 19:11:35,180 - ERROR - 1064 (42000): You have an error in your SQL syntax; check the manual that corresponds to your MySQL server version for the right syntax to use near 'INSER INTO `dcs`.`docker_containers` 
        (`name`,
        `status`,
       ' at line 1
2024-09-13 19:11:35,180 - ERROR - Error en la función `update_devnet_data` en el archivo `db_update_devnet`
