Error
HTTPSConnectionPool(host='10.224.241.25', port=443): Max retries exceeded with url: /api/table.json?content=sensors&id=15959&columns=lastvalue,objid,device,status,group,sensor&username=canadmin&password=Carrera01 (Caused by ConnectTimeoutError(<urllib3.connection.HTTPSConnection object at 0x7fd790dd2860>, 'Connection to 10.224.241.25 timed out. (connect timeout=None)'))
Traceback (most recent call last):
  File "/home/donkami/.local/lib/python3.10/site-packages/urllib3/connection.py", line 200, in _new_conn
    sock = connection.create_connection(
  File "/home/donkami/.local/lib/python3.10/site-packages/urllib3/util/connection.py", line 85, in create_connection
    raise err
  File "/home/donkami/.local/lib/python3.10/site-packages/urllib3/util/connection.py", line 73, in create_connection
    sock.connect(sa)
TimeoutError: [Errno 110] Connection timed out

The above exception was the direct cause of the following exception:

Traceback (most recent call last):
  File "/home/donkami/.local/lib/python3.10/site-packages/urllib3/connectionpool.py", line 790, in urlopen
    response = self._make_request(
  File "/home/donkami/.local/lib/python3.10/site-packages/urllib3/connectionpool.py", line 491, in _make_request
    raise new_e
  File "/home/donkami/.local/lib/python3.10/site-packages/urllib3/connectionpool.py", line 467, in _make_request
    self._validate_conn(conn)
  File "/home/donkami/.local/lib/python3.10/site-packages/urllib3/connectionpool.py", line 1092, in _validate_conn
    conn.connect()
  File "/home/donkami/.local/lib/python3.10/site-packages/urllib3/connection.py", line 604, in connect
    self.sock = sock = self._new_conn()
  File "/home/donkami/.local/lib/python3.10/site-packages/urllib3/connection.py", line 209, in _new_conn
    raise ConnectTimeoutError(
urllib3.exceptions.ConnectTimeoutError: (<urllib3.connection.HTTPSConnection object at 0x7fd790dd2860>, 'Connection to 10.224.241.25 timed out. (connect timeout=None)')

The above exception was the direct cause of the following exception:

Traceback (most recent call last):
  File "/home/donkami/.local/lib/python3.10/site-packages/requests/adapters.py", line 486, in send
    resp = conn.urlopen(
  File "/home/donkami/.local/lib/python3.10/site-packages/urllib3/connectionpool.py", line 844, in urlopen
    retries = retries.increment(
  File "/home/donkami/.local/lib/python3.10/site-packages/urllib3/util/retry.py", line 515, in increment
    raise MaxRetryError(_pool, url, reason) from reason  # type: ignore[arg-type]
urllib3.exceptions.MaxRetryError: HTTPSConnectionPool(host='10.224.241.25', port=443): Max retries exceeded with url: /api/table.json?content=sensors&id=15959&columns=lastvalue,objid,device,status,group,sensor&username=canadmin&password=Carrera01 (Caused by ConnectTimeoutError(<urllib3.connection.HTTPSConnection object at 0x7fd790dd2860>, 'Connection to 10.224.241.25 timed out. (connect timeout=None)'))

During handling of the above exception, another exception occurred:

Traceback (most recent call last):
  File "/home/donkami/Sona/devnet-candelaria/Services/Groups_Prtg/main.py", line 67, in get_data
    api_request = requests.get(api_endpoint, verify=False).json()
  File "/home/donkami/.local/lib/python3.10/site-packages/requests/api.py", line 73, in get
    return request("get", url, params=params, **kwargs)
  File "/home/donkami/.local/lib/python3.10/site-packages/requests/api.py", line 59, in request
    return session.request(method=method, url=url, **kwargs)
  File "/home/donkami/.local/lib/python3.10/site-packages/requests/sessions.py", line 589, in request
    resp = self.send(prep, **send_kwargs)
  File "/home/donkami/.local/lib/python3.10/site-packages/requests/sessions.py", line 703, in send
    r = adapter.send(request, **kwargs)
  File "/home/donkami/.local/lib/python3.10/site-packages/requests/adapters.py", line 507, in send
    raise ConnectTimeout(e, request=request)
requests.exceptions.ConnectTimeout: HTTPSConnectionPool(host='10.224.241.25', port=443): Max retries exceeded with url: /api/table.json?content=sensors&id=15959&columns=lastvalue,objid,device,status,group,sensor&username=canadmin&password=Carrera01 (Caused by ConnectTimeoutError(<urllib3.connection.HTTPSConnection object at 0x7fd790dd2860>, 'Connection to 10.224.241.25 timed out. (connect timeout=None)'))

Error
HTTPSConnectionPool(host='10.224.241.25', port=443): Max retries exceeded with url: /api/table.json?content=sensors&id=15959&columns=lastvalue,objid,device,status,group,sensor&username=canadmin&password=Carrera01 (Caused by ConnectTimeoutError(<urllib3.connection.HTTPSConnection object at 0x7fd790dd3010>, 'Connection to 10.224.241.25 timed out. (connect timeout=None)'))
Traceback (most recent call last):
  File "/home/donkami/.local/lib/python3.10/site-packages/urllib3/connection.py", line 200, in _new_conn
    sock = connection.create_connection(
  File "/home/donkami/.local/lib/python3.10/site-packages/urllib3/util/connection.py", line 85, in create_connection
    raise err
  File "/home/donkami/.local/lib/python3.10/site-packages/urllib3/util/connection.py", line 73, in create_connection
    sock.connect(sa)
TimeoutError: [Errno 110] Connection timed out

The above exception was the direct cause of the following exception:

Traceback (most recent call last):
  File "/home/donkami/.local/lib/python3.10/site-packages/urllib3/connectionpool.py", line 790, in urlopen
    response = self._make_request(
  File "/home/donkami/.local/lib/python3.10/site-packages/urllib3/connectionpool.py", line 491, in _make_request
    raise new_e
  File "/home/donkami/.local/lib/python3.10/site-packages/urllib3/connectionpool.py", line 467, in _make_request
    self._validate_conn(conn)
  File "/home/donkami/.local/lib/python3.10/site-packages/urllib3/connectionpool.py", line 1092, in _validate_conn
    conn.connect()
  File "/home/donkami/.local/lib/python3.10/site-packages/urllib3/connection.py", line 604, in connect
    self.sock = sock = self._new_conn()
  File "/home/donkami/.local/lib/python3.10/site-packages/urllib3/connection.py", line 209, in _new_conn
    raise ConnectTimeoutError(
urllib3.exceptions.ConnectTimeoutError: (<urllib3.connection.HTTPSConnection object at 0x7fd790dd3010>, 'Connection to 10.224.241.25 timed out. (connect timeout=None)')

The above exception was the direct cause of the following exception:

Traceback (most recent call last):
  File "/home/donkami/.local/lib/python3.10/site-packages/requests/adapters.py", line 486, in send
    resp = conn.urlopen(
  File "/home/donkami/.local/lib/python3.10/site-packages/urllib3/connectionpool.py", line 844, in urlopen
    retries = retries.increment(
  File "/home/donkami/.local/lib/python3.10/site-packages/urllib3/util/retry.py", line 515, in increment
    raise MaxRetryError(_pool, url, reason) from reason  # type: ignore[arg-type]
urllib3.exceptions.MaxRetryError: HTTPSConnectionPool(host='10.224.241.25', port=443): Max retries exceeded with url: /api/table.json?content=sensors&id=15959&columns=lastvalue,objid,device,status,group,sensor&username=canadmin&password=Carrera01 (Caused by ConnectTimeoutError(<urllib3.connection.HTTPSConnection object at 0x7fd790dd3010>, 'Connection to 10.224.241.25 timed out. (connect timeout=None)'))

During handling of the above exception, another exception occurred:

Traceback (most recent call last):
  File "/home/donkami/Sona/devnet-candelaria/Services/Groups_Prtg/main.py", line 67, in get_data
    api_request = requests.get(api_endpoint, verify=False).json()
  File "/home/donkami/.local/lib/python3.10/site-packages/requests/api.py", line 73, in get
    return request("get", url, params=params, **kwargs)
  File "/home/donkami/.local/lib/python3.10/site-packages/requests/api.py", line 59, in request
    return session.request(method=method, url=url, **kwargs)
  File "/home/donkami/.local/lib/python3.10/site-packages/requests/sessions.py", line 589, in request
    resp = self.send(prep, **send_kwargs)
  File "/home/donkami/.local/lib/python3.10/site-packages/requests/sessions.py", line 703, in send
    r = adapter.send(request, **kwargs)
  File "/home/donkami/.local/lib/python3.10/site-packages/requests/adapters.py", line 507, in send
    raise ConnectTimeout(e, request=request)
requests.exceptions.ConnectTimeout: HTTPSConnectionPool(host='10.224.241.25', port=443): Max retries exceeded with url: /api/table.json?content=sensors&id=15959&columns=lastvalue,objid,device,status,group,sensor&username=canadmin&password=Carrera01 (Caused by ConnectTimeoutError(<urllib3.connection.HTTPSConnection object at 0x7fd790dd3010>, 'Connection to 10.224.241.25 timed out. (connect timeout=None)'))

Error
HTTPSConnectionPool(host='10.224.241.25', port=443): Max retries exceeded with url: /api/table.json?content=sensors&id=15959&columns=lastvalue,objid,device,status,group,sensor&username=canadmin&password=Carrera01 (Caused by ConnectTimeoutError(<urllib3.connection.HTTPSConnection object at 0x7fd790dd38b0>, 'Connection to 10.224.241.25 timed out. (connect timeout=None)'))
Traceback (most recent call last):
  File "/home/donkami/.local/lib/python3.10/site-packages/urllib3/connection.py", line 200, in _new_conn
    sock = connection.create_connection(
  File "/home/donkami/.local/lib/python3.10/site-packages/urllib3/util/connection.py", line 85, in create_connection
    raise err
  File "/home/donkami/.local/lib/python3.10/site-packages/urllib3/util/connection.py", line 73, in create_connection
    sock.connect(sa)
TimeoutError: [Errno 110] Connection timed out

The above exception was the direct cause of the following exception:

Traceback (most recent call last):
  File "/home/donkami/.local/lib/python3.10/site-packages/urllib3/connectionpool.py", line 790, in urlopen
    response = self._make_request(
  File "/home/donkami/.local/lib/python3.10/site-packages/urllib3/connectionpool.py", line 491, in _make_request
    raise new_e
  File "/home/donkami/.local/lib/python3.10/site-packages/urllib3/connectionpool.py", line 467, in _make_request
    self._validate_conn(conn)
  File "/home/donkami/.local/lib/python3.10/site-packages/urllib3/connectionpool.py", line 1092, in _validate_conn
    conn.connect()
  File "/home/donkami/.local/lib/python3.10/site-packages/urllib3/connection.py", line 604, in connect
    self.sock = sock = self._new_conn()
  File "/home/donkami/.local/lib/python3.10/site-packages/urllib3/connection.py", line 209, in _new_conn
    raise ConnectTimeoutError(
urllib3.exceptions.ConnectTimeoutError: (<urllib3.connection.HTTPSConnection object at 0x7fd790dd38b0>, 'Connection to 10.224.241.25 timed out. (connect timeout=None)')

The above exception was the direct cause of the following exception:

Traceback (most recent call last):
  File "/home/donkami/.local/lib/python3.10/site-packages/requests/adapters.py", line 486, in send
    resp = conn.urlopen(
  File "/home/donkami/.local/lib/python3.10/site-packages/urllib3/connectionpool.py", line 844, in urlopen
    retries = retries.increment(
  File "/home/donkami/.local/lib/python3.10/site-packages/urllib3/util/retry.py", line 515, in increment
    raise MaxRetryError(_pool, url, reason) from reason  # type: ignore[arg-type]
urllib3.exceptions.MaxRetryError: HTTPSConnectionPool(host='10.224.241.25', port=443): Max retries exceeded with url: /api/table.json?content=sensors&id=15959&columns=lastvalue,objid,device,status,group,sensor&username=canadmin&password=Carrera01 (Caused by ConnectTimeoutError(<urllib3.connection.HTTPSConnection object at 0x7fd790dd38b0>, 'Connection to 10.224.241.25 timed out. (connect timeout=None)'))

During handling of the above exception, another exception occurred:

Traceback (most recent call last):
  File "/home/donkami/Sona/devnet-candelaria/Services/Groups_Prtg/main.py", line 67, in get_data
    api_request = requests.get(api_endpoint, verify=False).json()
  File "/home/donkami/.local/lib/python3.10/site-packages/requests/api.py", line 73, in get
    return request("get", url, params=params, **kwargs)
  File "/home/donkami/.local/lib/python3.10/site-packages/requests/api.py", line 59, in request
    return session.request(method=method, url=url, **kwargs)
  File "/home/donkami/.local/lib/python3.10/site-packages/requests/sessions.py", line 589, in request
    resp = self.send(prep, **send_kwargs)
  File "/home/donkami/.local/lib/python3.10/site-packages/requests/sessions.py", line 703, in send
    r = adapter.send(request, **kwargs)
  File "/home/donkami/.local/lib/python3.10/site-packages/requests/adapters.py", line 507, in send
    raise ConnectTimeout(e, request=request)
requests.exceptions.ConnectTimeout: HTTPSConnectionPool(host='10.224.241.25', port=443): Max retries exceeded with url: /api/table.json?content=sensors&id=15959&columns=lastvalue,objid,device,status,group,sensor&username=canadmin&password=Carrera01 (Caused by ConnectTimeoutError(<urllib3.connection.HTTPSConnection object at 0x7fd790dd38b0>, 'Connection to 10.224.241.25 timed out. (connect timeout=None)'))

Error
HTTPSConnectionPool(host='10.224.241.25', port=443): Max retries exceeded with url: /api/table.json?content=sensors&id=15959&columns=lastvalue,objid,device,status,group,sensor&username=canadmin&password=Carrera01 (Caused by ConnectTimeoutError(<urllib3.connection.HTTPSConnection object at 0x7fd790dd3880>, 'Connection to 10.224.241.25 timed out. (connect timeout=None)'))
Traceback (most recent call last):
  File "/home/donkami/.local/lib/python3.10/site-packages/urllib3/connection.py", line 200, in _new_conn
    sock = connection.create_connection(
  File "/home/donkami/.local/lib/python3.10/site-packages/urllib3/util/connection.py", line 85, in create_connection
    raise err
  File "/home/donkami/.local/lib/python3.10/site-packages/urllib3/util/connection.py", line 73, in create_connection
    sock.connect(sa)
TimeoutError: [Errno 110] Connection timed out

The above exception was the direct cause of the following exception:

Traceback (most recent call last):
  File "/home/donkami/.local/lib/python3.10/site-packages/urllib3/connectionpool.py", line 790, in urlopen
    response = self._make_request(
  File "/home/donkami/.local/lib/python3.10/site-packages/urllib3/connectionpool.py", line 491, in _make_request
    raise new_e
  File "/home/donkami/.local/lib/python3.10/site-packages/urllib3/connectionpool.py", line 467, in _make_request
    self._validate_conn(conn)
  File "/home/donkami/.local/lib/python3.10/site-packages/urllib3/connectionpool.py", line 1092, in _validate_conn
    conn.connect()
  File "/home/donkami/.local/lib/python3.10/site-packages/urllib3/connection.py", line 604, in connect
    self.sock = sock = self._new_conn()
  File "/home/donkami/.local/lib/python3.10/site-packages/urllib3/connection.py", line 209, in _new_conn
    raise ConnectTimeoutError(
urllib3.exceptions.ConnectTimeoutError: (<urllib3.connection.HTTPSConnection object at 0x7fd790dd3880>, 'Connection to 10.224.241.25 timed out. (connect timeout=None)')

The above exception was the direct cause of the following exception:

Traceback (most recent call last):
  File "/home/donkami/.local/lib/python3.10/site-packages/requests/adapters.py", line 486, in send
    resp = conn.urlopen(
  File "/home/donkami/.local/lib/python3.10/site-packages/urllib3/connectionpool.py", line 844, in urlopen
    retries = retries.increment(
  File "/home/donkami/.local/lib/python3.10/site-packages/urllib3/util/retry.py", line 515, in increment
    raise MaxRetryError(_pool, url, reason) from reason  # type: ignore[arg-type]
urllib3.exceptions.MaxRetryError: HTTPSConnectionPool(host='10.224.241.25', port=443): Max retries exceeded with url: /api/table.json?content=sensors&id=15959&columns=lastvalue,objid,device,status,group,sensor&username=canadmin&password=Carrera01 (Caused by ConnectTimeoutError(<urllib3.connection.HTTPSConnection object at 0x7fd790dd3880>, 'Connection to 10.224.241.25 timed out. (connect timeout=None)'))

During handling of the above exception, another exception occurred:

Traceback (most recent call last):
  File "/home/donkami/Sona/devnet-candelaria/Services/Groups_Prtg/main.py", line 67, in get_data
    api_request = requests.get(api_endpoint, verify=False).json()
  File "/home/donkami/.local/lib/python3.10/site-packages/requests/api.py", line 73, in get
    return request("get", url, params=params, **kwargs)
  File "/home/donkami/.local/lib/python3.10/site-packages/requests/api.py", line 59, in request
    return session.request(method=method, url=url, **kwargs)
  File "/home/donkami/.local/lib/python3.10/site-packages/requests/sessions.py", line 589, in request
    resp = self.send(prep, **send_kwargs)
  File "/home/donkami/.local/lib/python3.10/site-packages/requests/sessions.py", line 703, in send
    r = adapter.send(request, **kwargs)
  File "/home/donkami/.local/lib/python3.10/site-packages/requests/adapters.py", line 507, in send
    raise ConnectTimeout(e, request=request)
requests.exceptions.ConnectTimeout: HTTPSConnectionPool(host='10.224.241.25', port=443): Max retries exceeded with url: /api/table.json?content=sensors&id=15959&columns=lastvalue,objid,device,status,group,sensor&username=canadmin&password=Carrera01 (Caused by ConnectTimeoutError(<urllib3.connection.HTTPSConnection object at 0x7fd790dd3880>, 'Connection to 10.224.241.25 timed out. (connect timeout=None)'))

Error
HTTPSConnectionPool(host='10.224.241.25', port=443): Max retries exceeded with url: /api/table.json?content=sensors&id=15959&columns=lastvalue,objid,device,status,group,sensor&username=canadmin&password=Carrera01 (Caused by ConnectTimeoutError(<urllib3.connection.HTTPSConnection object at 0x7fd790dd2fe0>, 'Connection to 10.224.241.25 timed out. (connect timeout=None)'))
Traceback (most recent call last):
  File "/home/donkami/.local/lib/python3.10/site-packages/urllib3/connection.py", line 200, in _new_conn
    sock = connection.create_connection(
  File "/home/donkami/.local/lib/python3.10/site-packages/urllib3/util/connection.py", line 85, in create_connection
    raise err
  File "/home/donkami/.local/lib/python3.10/site-packages/urllib3/util/connection.py", line 73, in create_connection
    sock.connect(sa)
TimeoutError: [Errno 110] Connection timed out

The above exception was the direct cause of the following exception:

Traceback (most recent call last):
  File "/home/donkami/.local/lib/python3.10/site-packages/urllib3/connectionpool.py", line 790, in urlopen
    response = self._make_request(
  File "/home/donkami/.local/lib/python3.10/site-packages/urllib3/connectionpool.py", line 491, in _make_request
    raise new_e
  File "/home/donkami/.local/lib/python3.10/site-packages/urllib3/connectionpool.py", line 467, in _make_request
    self._validate_conn(conn)
  File "/home/donkami/.local/lib/python3.10/site-packages/urllib3/connectionpool.py", line 1092, in _validate_conn
    conn.connect()
  File "/home/donkami/.local/lib/python3.10/site-packages/urllib3/connection.py", line 604, in connect
    self.sock = sock = self._new_conn()
  File "/home/donkami/.local/lib/python3.10/site-packages/urllib3/connection.py", line 209, in _new_conn
    raise ConnectTimeoutError(
urllib3.exceptions.ConnectTimeoutError: (<urllib3.connection.HTTPSConnection object at 0x7fd790dd2fe0>, 'Connection to 10.224.241.25 timed out. (connect timeout=None)')

The above exception was the direct cause of the following exception:

Traceback (most recent call last):
  File "/home/donkami/.local/lib/python3.10/site-packages/requests/adapters.py", line 486, in send
    resp = conn.urlopen(
  File "/home/donkami/.local/lib/python3.10/site-packages/urllib3/connectionpool.py", line 844, in urlopen
    retries = retries.increment(
  File "/home/donkami/.local/lib/python3.10/site-packages/urllib3/util/retry.py", line 515, in increment
    raise MaxRetryError(_pool, url, reason) from reason  # type: ignore[arg-type]
urllib3.exceptions.MaxRetryError: HTTPSConnectionPool(host='10.224.241.25', port=443): Max retries exceeded with url: /api/table.json?content=sensors&id=15959&columns=lastvalue,objid,device,status,group,sensor&username=canadmin&password=Carrera01 (Caused by ConnectTimeoutError(<urllib3.connection.HTTPSConnection object at 0x7fd790dd2fe0>, 'Connection to 10.224.241.25 timed out. (connect timeout=None)'))

During handling of the above exception, another exception occurred:

Traceback (most recent call last):
  File "/home/donkami/Sona/devnet-candelaria/Services/Groups_Prtg/main.py", line 67, in get_data
    api_request = requests.get(api_endpoint, verify=False).json()
  File "/home/donkami/.local/lib/python3.10/site-packages/requests/api.py", line 73, in get
    return request("get", url, params=params, **kwargs)
  File "/home/donkami/.local/lib/python3.10/site-packages/requests/api.py", line 59, in request
    return session.request(method=method, url=url, **kwargs)
  File "/home/donkami/.local/lib/python3.10/site-packages/requests/sessions.py", line 589, in request
    resp = self.send(prep, **send_kwargs)
  File "/home/donkami/.local/lib/python3.10/site-packages/requests/sessions.py", line 703, in send
    r = adapter.send(request, **kwargs)
  File "/home/donkami/.local/lib/python3.10/site-packages/requests/adapters.py", line 507, in send
    raise ConnectTimeout(e, request=request)
requests.exceptions.ConnectTimeout: HTTPSConnectionPool(host='10.224.241.25', port=443): Max retries exceeded with url: /api/table.json?content=sensors&id=15959&columns=lastvalue,objid,device,status,group,sensor&username=canadmin&password=Carrera01 (Caused by ConnectTimeoutError(<urllib3.connection.HTTPSConnection object at 0x7fd790dd2fe0>, 'Connection to 10.224.241.25 timed out. (connect timeout=None)'))

Error
'optional_group'
Traceback (most recent call last):
  File "/home/donkami/Sona/devnet-candelaria/Services/Groups_Prtg/main.py", line 88, in get_data
    values = [(item["device"], item["group"], item["status"], item["objid"], item["sensor"], item["lastvalue"], item["optional_group"]) for item in prtg_data]
  File "/home/donkami/Sona/devnet-candelaria/Services/Groups_Prtg/main.py", line 88, in <listcomp>
    values = [(item["device"], item["group"], item["status"], item["objid"], item["sensor"], item["lastvalue"], item["optional_group"]) for item in prtg_data]
KeyError: 'optional_group'

