2024-07-15 16:11:48,506 - ERROR: Error al obtener la informacion de los DISPOSITIVOS desde la API
2024-07-15 16:11:48,509 - ERROR: Traceback (most recent call last):
  File "/home/donkami/.local/lib/python3.10/site-packages/urllib3/connection.py", line 200, in _new_conn
    sock = connection.create_connection(
  File "/home/donkami/.local/lib/python3.10/site-packages/urllib3/util/connection.py", line 85, in create_connection
    raise err
  File "/home/donkami/.local/lib/python3.10/site-packages/urllib3/util/connection.py", line 73, in create_connection
    sock.connect(sa)
ConnectionRefusedError: [Errno 111] Connection refused

The above exception was the direct cause of the following exception:

Traceback (most recent call last):
  File "/home/donkami/.local/lib/python3.10/site-packages/urllib3/connectionpool.py", line 790, in urlopen
    response = self._make_request(
  File "/home/donkami/.local/lib/python3.10/site-packages/urllib3/connectionpool.py", line 496, in _make_request
    conn.request(
  File "/home/donkami/.local/lib/python3.10/site-packages/urllib3/connection.py", line 388, in request
    self.endheaders()
  File "/usr/lib/python3.10/http/client.py", line 1278, in endheaders
    self._send_output(message_body, encode_chunked=encode_chunked)
  File "/usr/lib/python3.10/http/client.py", line 1038, in _send_output
    self.send(msg)
  File "/usr/lib/python3.10/http/client.py", line 976, in send
    self.connect()
  File "/home/donkami/.local/lib/python3.10/site-packages/urllib3/connection.py", line 236, in connect
    self.sock = self._new_conn()
  File "/home/donkami/.local/lib/python3.10/site-packages/urllib3/connection.py", line 215, in _new_conn
    raise NewConnectionError(
urllib3.exceptions.NewConnectionError: <urllib3.connection.HTTPConnection object at 0x7fd634fd9690>: Failed to establish a new connection: [Errno 111] Connection refused

The above exception was the direct cause of the following exception:

Traceback (most recent call last):
  File "/home/donkami/.local/lib/python3.10/site-packages/requests/adapters.py", line 486, in send
    resp = conn.urlopen(
  File "/home/donkami/.local/lib/python3.10/site-packages/urllib3/connectionpool.py", line 844, in urlopen
    retries = retries.increment(
  File "/home/donkami/.local/lib/python3.10/site-packages/urllib3/util/retry.py", line 515, in increment
    raise MaxRetryError(_pool, url, reason) from reason  # type: ignore[arg-type]
urllib3.exceptions.MaxRetryError: HTTPConnectionPool(host='localhost', port=3001): Max retries exceeded with url: /api/v1/candelaria/devices (Caused by NewConnectionError('<urllib3.connection.HTTPConnection object at 0x7fd634fd9690>: Failed to establish a new connection: [Errno 111] Connection refused'))

During handling of the above exception, another exception occurred:

Traceback (most recent call last):
  File "/home/donkami/Sona/devnet-candelaria/Services/Camaras/ups.py", line 108, in get_api_devices_data
    data_devices = requests.get(API_DEVICES, verify=False).json()
  File "/home/donkami/.local/lib/python3.10/site-packages/requests/api.py", line 73, in get
    return request("get", url, params=params, **kwargs)
  File "/home/donkami/.local/lib/python3.10/site-packages/requests/api.py", line 59, in request
    return session.request(method=method, url=url, **kwargs)
  File "/home/donkami/.local/lib/python3.10/site-packages/requests/sessions.py", line 589, in request
    resp = self.send(prep, **send_kwargs)
  File "/home/donkami/.local/lib/python3.10/site-packages/requests/sessions.py", line 703, in send
    r = adapter.send(request, **kwargs)
  File "/home/donkami/.local/lib/python3.10/site-packages/requests/adapters.py", line 519, in send
    raise ConnectionError(e, request=request)
requests.exceptions.ConnectionError: HTTPConnectionPool(host='localhost', port=3001): Max retries exceeded with url: /api/v1/candelaria/devices (Caused by NewConnectionError('<urllib3.connection.HTTPConnection object at 0x7fd634fd9690>: Failed to establish a new connection: [Errno 111] Connection refused'))

2024-07-15 16:11:48,510 - ERROR: Error detallado:
2024-07-15 16:11:48,510 - ERROR: HTTPConnectionPool(host='localhost', port=3001): Max retries exceeded with url: /api/v1/candelaria/devices (Caused by NewConnectionError('<urllib3.connection.HTTPConnection object at 0x7fd634fd9690>: Failed to establish a new connection: [Errno 111] Connection refused'))
2024-07-15 16:11:48,511 - ERROR: Error al obtener la informacion de las UPS desde la API
2024-07-15 16:11:48,511 - ERROR: Traceback (most recent call last):
  File "/home/donkami/.local/lib/python3.10/site-packages/urllib3/connection.py", line 200, in _new_conn
    sock = connection.create_connection(
  File "/home/donkami/.local/lib/python3.10/site-packages/urllib3/util/connection.py", line 85, in create_connection
    raise err
  File "/home/donkami/.local/lib/python3.10/site-packages/urllib3/util/connection.py", line 73, in create_connection
    sock.connect(sa)
ConnectionRefusedError: [Errno 111] Connection refused

The above exception was the direct cause of the following exception:

Traceback (most recent call last):
  File "/home/donkami/.local/lib/python3.10/site-packages/urllib3/connectionpool.py", line 790, in urlopen
    response = self._make_request(
  File "/home/donkami/.local/lib/python3.10/site-packages/urllib3/connectionpool.py", line 496, in _make_request
    conn.request(
  File "/home/donkami/.local/lib/python3.10/site-packages/urllib3/connection.py", line 388, in request
    self.endheaders()
  File "/usr/lib/python3.10/http/client.py", line 1278, in endheaders
    self._send_output(message_body, encode_chunked=encode_chunked)
  File "/usr/lib/python3.10/http/client.py", line 1038, in _send_output
    self.send(msg)
  File "/usr/lib/python3.10/http/client.py", line 976, in send
    self.connect()
  File "/home/donkami/.local/lib/python3.10/site-packages/urllib3/connection.py", line 236, in connect
    self.sock = self._new_conn()
  File "/home/donkami/.local/lib/python3.10/site-packages/urllib3/connection.py", line 215, in _new_conn
    raise NewConnectionError(
urllib3.exceptions.NewConnectionError: <urllib3.connection.HTTPConnection object at 0x7fd634fda110>: Failed to establish a new connection: [Errno 111] Connection refused

The above exception was the direct cause of the following exception:

Traceback (most recent call last):
  File "/home/donkami/.local/lib/python3.10/site-packages/requests/adapters.py", line 486, in send
    resp = conn.urlopen(
  File "/home/donkami/.local/lib/python3.10/site-packages/urllib3/connectionpool.py", line 844, in urlopen
    retries = retries.increment(
  File "/home/donkami/.local/lib/python3.10/site-packages/urllib3/util/retry.py", line 515, in increment
    raise MaxRetryError(_pool, url, reason) from reason  # type: ignore[arg-type]
urllib3.exceptions.MaxRetryError: HTTPConnectionPool(host='localhost', port=3001): Max retries exceeded with url: /api/v1/candelaria/ups (Caused by NewConnectionError('<urllib3.connection.HTTPConnection object at 0x7fd634fda110>: Failed to establish a new connection: [Errno 111] Connection refused'))

During handling of the above exception, another exception occurred:

Traceback (most recent call last):
  File "/home/donkami/Sona/devnet-candelaria/Services/Camaras/ups.py", line 92, in get_api_ups_data
    data_ups = requests.get(API_UPS, verify=False).json()
  File "/home/donkami/.local/lib/python3.10/site-packages/requests/api.py", line 73, in get
    return request("get", url, params=params, **kwargs)
  File "/home/donkami/.local/lib/python3.10/site-packages/requests/api.py", line 59, in request
    return session.request(method=method, url=url, **kwargs)
  File "/home/donkami/.local/lib/python3.10/site-packages/requests/sessions.py", line 589, in request
    resp = self.send(prep, **send_kwargs)
  File "/home/donkami/.local/lib/python3.10/site-packages/requests/sessions.py", line 703, in send
    r = adapter.send(request, **kwargs)
  File "/home/donkami/.local/lib/python3.10/site-packages/requests/adapters.py", line 519, in send
    raise ConnectionError(e, request=request)
requests.exceptions.ConnectionError: HTTPConnectionPool(host='localhost', port=3001): Max retries exceeded with url: /api/v1/candelaria/ups (Caused by NewConnectionError('<urllib3.connection.HTTPConnection object at 0x7fd634fda110>: Failed to establish a new connection: [Errno 111] Connection refused'))

2024-07-15 16:11:48,511 - ERROR: Error detallado:
2024-07-15 16:11:48,511 - ERROR: HTTPConnectionPool(host='localhost', port=3001): Max retries exceeded with url: /api/v1/candelaria/ups (Caused by NewConnectionError('<urllib3.connection.HTTPConnection object at 0x7fd634fda110>: Failed to establish a new connection: [Errno 111] Connection refused'))
2024-07-15 16:11:48,511 - ERROR: Hubo un error en la funcion `define_ups_status`: Error al obtener la informaci√≥n de la API
2024-07-28 23:26:18,729 - ERROR: Error al obtener la informacion de las UPS desde la API
2024-07-28 23:26:18,729 - ERROR - Error al obtener la informacion de las UPS desde la API
2024-07-28 23:26:18,733 - ERROR: Traceback (most recent call last):
  File "/home/donkami/.local/lib/python3.10/site-packages/urllib3/connection.py", line 200, in _new_conn
    sock = connection.create_connection(
  File "/home/donkami/.local/lib/python3.10/site-packages/urllib3/util/connection.py", line 85, in create_connection
    raise err
  File "/home/donkami/.local/lib/python3.10/site-packages/urllib3/util/connection.py", line 73, in create_connection
    sock.connect(sa)
ConnectionRefusedError: [Errno 111] Connection refused

The above exception was the direct cause of the following exception:

Traceback (most recent call last):
  File "/home/donkami/.local/lib/python3.10/site-packages/urllib3/connectionpool.py", line 790, in urlopen
    response = self._make_request(
  File "/home/donkami/.local/lib/python3.10/site-packages/urllib3/connectionpool.py", line 496, in _make_request
    conn.request(
  File "/home/donkami/.local/lib/python3.10/site-packages/urllib3/connection.py", line 388, in request
    self.endheaders()
  File "/usr/lib/python3.10/http/client.py", line 1278, in endheaders
    self._send_output(message_body, encode_chunked=encode_chunked)
  File "/usr/lib/python3.10/http/client.py", line 1038, in _send_output
    self.send(msg)
  File "/usr/lib/python3.10/http/client.py", line 976, in send
    self.connect()
  File "/home/donkami/.local/lib/python3.10/site-packages/urllib3/connection.py", line 236, in connect
    self.sock = self._new_conn()
  File "/home/donkami/.local/lib/python3.10/site-packages/urllib3/connection.py", line 215, in _new_conn
    raise NewConnectionError(
urllib3.exceptions.NewConnectionError: <urllib3.connection.HTTPConnection object at 0x7f06866a20b0>: Failed to establish a new connection: [Errno 111] Connection refused

The above exception was the direct cause of the following exception:

Traceback (most recent call last):
  File "/home/donkami/.local/lib/python3.10/site-packages/requests/adapters.py", line 486, in send
    resp = conn.urlopen(
  File "/home/donkami/.local/lib/python3.10/site-packages/urllib3/connectionpool.py", line 844, in urlopen
    retries = retries.increment(
  File "/home/donkami/.local/lib/python3.10/site-packages/urllib3/util/retry.py", line 515, in increment
    raise MaxRetryError(_pool, url, reason) from reason  # type: ignore[arg-type]
urllib3.exceptions.MaxRetryError: HTTPConnectionPool(host='localhost', port=3001): Max retries exceeded with url: /api/v1/candelaria/ups (Caused by NewConnectionError('<urllib3.connection.HTTPConnection object at 0x7f06866a20b0>: Failed to establish a new connection: [Errno 111] Connection refused'))

During handling of the above exception, another exception occurred:

Traceback (most recent call last):
  File "/home/donkami/Sona/devnet-candelaria/Services/Camaras/ups.py", line 79, in get_api_ups_data
    data_ups = requests.get(API_UPS, verify=False).json()
  File "/home/donkami/.local/lib/python3.10/site-packages/requests/api.py", line 73, in get
    return request("get", url, params=params, **kwargs)
  File "/home/donkami/.local/lib/python3.10/site-packages/requests/api.py", line 59, in request
    return session.request(method=method, url=url, **kwargs)
  File "/home/donkami/.local/lib/python3.10/site-packages/requests/sessions.py", line 589, in request
    resp = self.send(prep, **send_kwargs)
  File "/home/donkami/.local/lib/python3.10/site-packages/requests/sessions.py", line 703, in send
    r = adapter.send(request, **kwargs)
  File "/home/donkami/.local/lib/python3.10/site-packages/requests/adapters.py", line 519, in send
    raise ConnectionError(e, request=request)
requests.exceptions.ConnectionError: HTTPConnectionPool(host='localhost', port=3001): Max retries exceeded with url: /api/v1/candelaria/ups (Caused by NewConnectionError('<urllib3.connection.HTTPConnection object at 0x7f06866a20b0>: Failed to establish a new connection: [Errno 111] Connection refused'))

2024-07-28 23:26:18,733 - ERROR - Traceback (most recent call last):
  File "/home/donkami/.local/lib/python3.10/site-packages/urllib3/connection.py", line 200, in _new_conn
    sock = connection.create_connection(
  File "/home/donkami/.local/lib/python3.10/site-packages/urllib3/util/connection.py", line 85, in create_connection
    raise err
  File "/home/donkami/.local/lib/python3.10/site-packages/urllib3/util/connection.py", line 73, in create_connection
    sock.connect(sa)
ConnectionRefusedError: [Errno 111] Connection refused

The above exception was the direct cause of the following exception:

Traceback (most recent call last):
  File "/home/donkami/.local/lib/python3.10/site-packages/urllib3/connectionpool.py", line 790, in urlopen
    response = self._make_request(
  File "/home/donkami/.local/lib/python3.10/site-packages/urllib3/connectionpool.py", line 496, in _make_request
    conn.request(
  File "/home/donkami/.local/lib/python3.10/site-packages/urllib3/connection.py", line 388, in request
    self.endheaders()
  File "/usr/lib/python3.10/http/client.py", line 1278, in endheaders
    self._send_output(message_body, encode_chunked=encode_chunked)
  File "/usr/lib/python3.10/http/client.py", line 1038, in _send_output
    self.send(msg)
  File "/usr/lib/python3.10/http/client.py", line 976, in send
    self.connect()
  File "/home/donkami/.local/lib/python3.10/site-packages/urllib3/connection.py", line 236, in connect
    self.sock = self._new_conn()
  File "/home/donkami/.local/lib/python3.10/site-packages/urllib3/connection.py", line 215, in _new_conn
    raise NewConnectionError(
urllib3.exceptions.NewConnectionError: <urllib3.connection.HTTPConnection object at 0x7f06866a20b0>: Failed to establish a new connection: [Errno 111] Connection refused

The above exception was the direct cause of the following exception:

Traceback (most recent call last):
  File "/home/donkami/.local/lib/python3.10/site-packages/requests/adapters.py", line 486, in send
    resp = conn.urlopen(
  File "/home/donkami/.local/lib/python3.10/site-packages/urllib3/connectionpool.py", line 844, in urlopen
    retries = retries.increment(
  File "/home/donkami/.local/lib/python3.10/site-packages/urllib3/util/retry.py", line 515, in increment
    raise MaxRetryError(_pool, url, reason) from reason  # type: ignore[arg-type]
urllib3.exceptions.MaxRetryError: HTTPConnectionPool(host='localhost', port=3001): Max retries exceeded with url: /api/v1/candelaria/ups (Caused by NewConnectionError('<urllib3.connection.HTTPConnection object at 0x7f06866a20b0>: Failed to establish a new connection: [Errno 111] Connection refused'))

During handling of the above exception, another exception occurred:

Traceback (most recent call last):
  File "/home/donkami/Sona/devnet-candelaria/Services/Camaras/ups.py", line 79, in get_api_ups_data
    data_ups = requests.get(API_UPS, verify=False).json()
  File "/home/donkami/.local/lib/python3.10/site-packages/requests/api.py", line 73, in get
    return request("get", url, params=params, **kwargs)
  File "/home/donkami/.local/lib/python3.10/site-packages/requests/api.py", line 59, in request
    return session.request(method=method, url=url, **kwargs)
  File "/home/donkami/.local/lib/python3.10/site-packages/requests/sessions.py", line 589, in request
    resp = self.send(prep, **send_kwargs)
  File "/home/donkami/.local/lib/python3.10/site-packages/requests/sessions.py", line 703, in send
    r = adapter.send(request, **kwargs)
  File "/home/donkami/.local/lib/python3.10/site-packages/requests/adapters.py", line 519, in send
    raise ConnectionError(e, request=request)
requests.exceptions.ConnectionError: HTTPConnectionPool(host='localhost', port=3001): Max retries exceeded with url: /api/v1/candelaria/ups (Caused by NewConnectionError('<urllib3.connection.HTTPConnection object at 0x7f06866a20b0>: Failed to establish a new connection: [Errno 111] Connection refused'))

2024-07-28 23:26:18,734 - ERROR: Error detallado:
2024-07-28 23:26:18,734 - ERROR - Error detallado:
2024-07-28 23:26:18,734 - ERROR: HTTPConnectionPool(host='localhost', port=3001): Max retries exceeded with url: /api/v1/candelaria/ups (Caused by NewConnectionError('<urllib3.connection.HTTPConnection object at 0x7f06866a20b0>: Failed to establish a new connection: [Errno 111] Connection refused'))
2024-07-28 23:26:18,734 - ERROR - HTTPConnectionPool(host='localhost', port=3001): Max retries exceeded with url: /api/v1/candelaria/ups (Caused by NewConnectionError('<urllib3.connection.HTTPConnection object at 0x7f06866a20b0>: Failed to establish a new connection: [Errno 111] Connection refused'))
2024-07-28 23:26:18,734 - ERROR: Hubo un error en la funcion `define_ups_status`: Error al obtener la informaci√≥n de la API
2024-07-28 23:26:18,734 - ERROR - Hubo un error en la funcion `define_ups_status`: Error al obtener la informaci√≥n de la API
2024-07-28 23:26:18,734 - ERROR: Traceback (most recent call last):
  File "/home/donkami/Sona/devnet-candelaria/Services/Camaras/main.py", line 127, in get_devices_data
    ups_status = devices.get('ups_status', 0)
AttributeError: 'list' object has no attribute 'get'

2024-07-28 23:26:18,734 - ERROR - Traceback (most recent call last):
  File "/home/donkami/Sona/devnet-candelaria/Services/Camaras/main.py", line 127, in get_devices_data
    ups_status = devices.get('ups_status', 0)
AttributeError: 'list' object has no attribute 'get'

2024-07-28 23:26:18,734 - ERROR: 10.225.5.98
2024-07-28 23:26:18,734 - ERROR - 10.225.5.98
2024-07-28 23:27:16,930 - ERROR: Hubo un error en la funcion `define_ups_status`: 'cisco_device_name'
2024-07-28 23:27:16,930 - ERROR - Hubo un error en la funcion `define_ups_status`: 'cisco_device_name'
2024-07-28 23:27:16,930 - ERROR: Traceback (most recent call last):
  File "/home/donkami/Sona/devnet-candelaria/Services/Camaras/main.py", line 127, in get_devices_data
    ups_status = devices.get('ups_status', 0)
AttributeError: 'list' object has no attribute 'get'

2024-07-28 23:27:16,930 - ERROR - Traceback (most recent call last):
  File "/home/donkami/Sona/devnet-candelaria/Services/Camaras/main.py", line 127, in get_devices_data
    ups_status = devices.get('ups_status', 0)
AttributeError: 'list' object has no attribute 'get'

2024-07-28 23:27:16,931 - ERROR: 10.225.5.98
2024-07-28 23:27:16,931 - ERROR - 10.225.5.98
2024-07-28 23:29:29,680 - ERROR: Hubo un error en la funcion `define_ups_status`: 'cisco_device_name'
2024-07-28 23:29:29,680 - ERROR - Hubo un error en la funcion `define_ups_status`: 'cisco_device_name'
2024-07-28 23:29:29,680 - ERROR: Traceback (most recent call last):
  File "/home/donkami/Sona/devnet-candelaria/Services/Camaras/main.py", line 127, in get_devices_data
    ups_status = devices.get('ups_status', 0)
AttributeError: 'list' object has no attribute 'get'

2024-07-28 23:29:29,680 - ERROR - Traceback (most recent call last):
  File "/home/donkami/Sona/devnet-candelaria/Services/Camaras/main.py", line 127, in get_devices_data
    ups_status = devices.get('ups_status', 0)
AttributeError: 'list' object has no attribute 'get'

2024-07-28 23:29:29,680 - ERROR: 10.225.5.98
2024-07-28 23:29:29,680 - ERROR - 10.225.5.98
2024-07-28 23:30:38,618 - ERROR: Hubo un error en la funcion `define_ups_status`: 'cisco_device_name'
2024-07-28 23:30:38,618 - ERROR - Hubo un error en la funcion `define_ups_status`: 'cisco_device_name'
2024-07-28 23:30:38,619 - ERROR: Traceback (most recent call last):
  File "/home/donkami/Sona/devnet-candelaria/Services/Camaras/main.py", line 127, in get_devices_data
    print(ups_status)
UnboundLocalError: local variable 'ups_status' referenced before assignment

2024-07-28 23:30:38,619 - ERROR - Traceback (most recent call last):
  File "/home/donkami/Sona/devnet-candelaria/Services/Camaras/main.py", line 127, in get_devices_data
    print(ups_status)
UnboundLocalError: local variable 'ups_status' referenced before assignment

2024-07-28 23:30:38,619 - ERROR: 10.225.5.98
2024-07-28 23:30:38,619 - ERROR - 10.225.5.98
2024-07-28 23:31:27,139 - ERROR: Hubo un error en la funcion `define_ups_status`: 'cisco_device_name'
2024-07-28 23:31:27,139 - ERROR - Hubo un error en la funcion `define_ups_status`: 'cisco_device_name'
2024-07-28 23:31:27,140 - ERROR: Traceback (most recent call last):
  File "/home/donkami/Sona/devnet-candelaria/Services/Camaras/main.py", line 128, in get_devices_data
    ups_status = devices.get('ups_status', 0)
AttributeError: 'list' object has no attribute 'get'

2024-07-28 23:31:27,140 - ERROR - Traceback (most recent call last):
  File "/home/donkami/Sona/devnet-candelaria/Services/Camaras/main.py", line 128, in get_devices_data
    ups_status = devices.get('ups_status', 0)
AttributeError: 'list' object has no attribute 'get'

2024-07-28 23:31:27,140 - ERROR: 10.225.5.98
2024-07-28 23:31:27,140 - ERROR - 10.225.5.98
2024-07-28 23:32:17,380 - ERROR: Hubo un error en la funcion `define_ups_status`: 'cisco_device_name'
2024-07-28 23:32:17,380 - ERROR - Hubo un error en la funcion `define_ups_status`: 'cisco_device_name'
2024-07-28 23:32:24,076 - ERROR: Hubo un error en la funcion `define_ups_status`: 'cisco_device_name'
2024-07-28 23:32:24,076 - ERROR - Hubo un error en la funcion `define_ups_status`: 'cisco_device_name'
2024-07-28 23:33:10,030 - ERROR: Hubo un error en la funcion `define_ups_status`: 'cisco_device_name'
2024-07-28 23:33:10,030 - ERROR - Hubo un error en la funcion `define_ups_status`: 'cisco_device_name'
2024-07-28 23:34:30,933 - ERROR: Hubo un error en la funcion `define_ups_status`: 'str' object does not support item assignment
2024-07-28 23:34:30,933 - ERROR - Hubo un error en la funcion `define_ups_status`: 'str' object does not support item assignment
2024-07-28 23:34:30,944 - ERROR: Traceback (most recent call last):
  File "/home/donkami/.local/lib/python3.10/site-packages/mysql/connector/connection_cext.py", line 611, in cmd_query
    self._cmysql.query(
_mysql_connector.MySQLInterfaceError: Incorrect integer value: 'None' for column 'ups_status' at row 1

The above exception was the direct cause of the following exception:

Traceback (most recent call last):
  File "/home/donkami/Sona/devnet-candelaria/Services/Camaras/main.py", line 132, in get_devices_data
    cursor.execute(query)
  File "/home/donkami/.local/lib/python3.10/site-packages/mysql/connector/cursor_cext.py", line 330, in execute
    result = self._cnx.cmd_query(
  File "/home/donkami/.local/lib/python3.10/site-packages/mysql/connector/connection_cext.py", line 619, in cmd_query
    raise get_mysql_exception(
mysql.connector.errors.DatabaseError: 1366 (HY000): Incorrect integer value: 'None' for column 'ups_status' at row 1

2024-07-28 23:34:30,944 - ERROR - Traceback (most recent call last):
  File "/home/donkami/.local/lib/python3.10/site-packages/mysql/connector/connection_cext.py", line 611, in cmd_query
    self._cmysql.query(
_mysql_connector.MySQLInterfaceError: Incorrect integer value: 'None' for column 'ups_status' at row 1

The above exception was the direct cause of the following exception:

Traceback (most recent call last):
  File "/home/donkami/Sona/devnet-candelaria/Services/Camaras/main.py", line 132, in get_devices_data
    cursor.execute(query)
  File "/home/donkami/.local/lib/python3.10/site-packages/mysql/connector/cursor_cext.py", line 330, in execute
    result = self._cnx.cmd_query(
  File "/home/donkami/.local/lib/python3.10/site-packages/mysql/connector/connection_cext.py", line 619, in cmd_query
    raise get_mysql_exception(
mysql.connector.errors.DatabaseError: 1366 (HY000): Incorrect integer value: 'None' for column 'ups_status' at row 1

2024-07-28 23:34:30,944 - ERROR: 10.225.5.98
2024-07-28 23:34:30,944 - ERROR - 10.225.5.98
Error
list indices must be integers or slices, not str
Traceback (most recent call last):
  File "/home/donkami/Sona/devnet-candelaria/Services/Groups_Prtg/main.py", line 89, in get_data
    if data["sensors"] != []:
TypeError: list indices must be integers or slices, not str

Error
list indices must be integers or slices, not str
Traceback (most recent call last):
  File "/home/donkami/Sona/devnet-candelaria/Services/Groups_Prtg/main.py", line 89, in get_data
    if len(data["sensors"]) != 0:
TypeError: list indices must be integers or slices, not str

Error
list indices must be integers or slices, not str
Traceback (most recent call last):
  File "/home/donkami/Sona/devnet-candelaria/Services/Groups_Prtg/main.py", line 89, in get_data
    if len(data["sensors"]) != 0:
TypeError: list indices must be integers or slices, not str

2024-08-20 22:37:03,715 - ERROR - Error en funcion INTERFACES DESCRIPTION
2024-08-20 22:37:03,715 - ERROR - Error en funcion INTERFACES DESCRIPTION
2024-08-20 22:37:03,715 - ERROR - Error en funcion INTERFACES DESCRIPTION
2024-08-20 22:37:03,715 - ERROR - Error en funcion INTERFACES DESCRIPTION
2024-08-20 22:37:03,715 - ERROR - Error en funcion INTERFACES DESCRIPTION
2024-08-20 22:37:03,715 - ERROR - Error en funcion INTERFACES DESCRIPTION
2024-08-20 22:37:03,715 - ERROR - Error en funcion INTERFACES DESCRIPTION
2024-08-20 22:37:03,723 - ERROR - [Errno 110] Connection timed out
2024-08-20 22:37:03,723 - ERROR - [Errno 110] Connection timed out
2024-08-20 22:37:03,723 - ERROR - [Errno 110] Connection timed out
2024-08-20 22:37:03,723 - ERROR - [Errno 110] Connection timed out
2024-08-20 22:37:03,723 - ERROR - [Errno 110] Connection timed out
2024-08-20 22:37:03,723 - ERROR - [Errno 110] Connection timed out
2024-08-20 22:37:03,723 - ERROR - [Errno 110] Connection timed out
2024-08-20 22:37:03,724 - ERROR - Traceback (most recent call last):
  File "/home/donkami/Sona/devnet-candelaria/Services/InfraGeneral/interfaces_descriptions.py", line 25, in get_interfaces_descriptions
    client.connect(hostname=ip_switch, port=22, username='roadmin', password='C4nd3*2023')
  File "/home/donkami/.local/lib/python3.10/site-packages/paramiko/client.py", line 386, in connect
    sock.connect(addr)
TimeoutError: [Errno 110] Connection timed out

2024-08-20 22:37:03,724 - ERROR - Traceback (most recent call last):
  File "/home/donkami/Sona/devnet-candelaria/Services/InfraGeneral/interfaces_descriptions.py", line 25, in get_interfaces_descriptions
    client.connect(hostname=ip_switch, port=22, username='roadmin', password='C4nd3*2023')
  File "/home/donkami/.local/lib/python3.10/site-packages/paramiko/client.py", line 386, in connect
    sock.connect(addr)
TimeoutError: [Errno 110] Connection timed out

2024-08-20 22:37:03,724 - ERROR - Traceback (most recent call last):
  File "/home/donkami/Sona/devnet-candelaria/Services/InfraGeneral/interfaces_descriptions.py", line 25, in get_interfaces_descriptions
    client.connect(hostname=ip_switch, port=22, username='roadmin', password='C4nd3*2023')
  File "/home/donkami/.local/lib/python3.10/site-packages/paramiko/client.py", line 386, in connect
    sock.connect(addr)
TimeoutError: [Errno 110] Connection timed out

2024-08-20 22:37:03,724 - ERROR - Traceback (most recent call last):
  File "/home/donkami/Sona/devnet-candelaria/Services/InfraGeneral/interfaces_descriptions.py", line 25, in get_interfaces_descriptions
    client.connect(hostname=ip_switch, port=22, username='roadmin', password='C4nd3*2023')
  File "/home/donkami/.local/lib/python3.10/site-packages/paramiko/client.py", line 386, in connect
    sock.connect(addr)
TimeoutError: [Errno 110] Connection timed out

2024-08-20 22:37:03,724 - ERROR - Traceback (most recent call last):
  File "/home/donkami/Sona/devnet-candelaria/Services/InfraGeneral/interfaces_descriptions.py", line 25, in get_interfaces_descriptions
    client.connect(hostname=ip_switch, port=22, username='roadmin', password='C4nd3*2023')
  File "/home/donkami/.local/lib/python3.10/site-packages/paramiko/client.py", line 386, in connect
    sock.connect(addr)
TimeoutError: [Errno 110] Connection timed out

2024-08-20 22:37:03,724 - ERROR - Traceback (most recent call last):
  File "/home/donkami/Sona/devnet-candelaria/Services/InfraGeneral/interfaces_descriptions.py", line 25, in get_interfaces_descriptions
    client.connect(hostname=ip_switch, port=22, username='roadmin', password='C4nd3*2023')
  File "/home/donkami/.local/lib/python3.10/site-packages/paramiko/client.py", line 386, in connect
    sock.connect(addr)
TimeoutError: [Errno 110] Connection timed out

2024-08-20 22:37:03,724 - ERROR - Traceback (most recent call last):
  File "/home/donkami/Sona/devnet-candelaria/Services/InfraGeneral/interfaces_descriptions.py", line 25, in get_interfaces_descriptions
    client.connect(hostname=ip_switch, port=22, username='roadmin', password='C4nd3*2023')
  File "/home/donkami/.local/lib/python3.10/site-packages/paramiko/client.py", line 386, in connect
    sock.connect(addr)
TimeoutError: [Errno 110] Connection timed out

2024-08-20 22:39:16,832 - ERROR - Error en funcion INTERFACES DESCRIPTION
2024-08-20 22:39:16,832 - ERROR - Error en funcion INTERFACES DESCRIPTION
2024-08-20 22:39:16,832 - ERROR - Error en funcion INTERFACES DESCRIPTION
2024-08-20 22:39:16,832 - ERROR - Error en funcion INTERFACES DESCRIPTION
2024-08-20 22:39:16,832 - ERROR - Error en funcion INTERFACES DESCRIPTION
2024-08-20 22:39:16,832 - ERROR - Error en funcion INTERFACES DESCRIPTION
2024-08-20 22:39:16,832 - ERROR - Error en funcion INTERFACES DESCRIPTION
2024-08-20 22:39:16,833 - ERROR - [Errno 110] Connection timed out
2024-08-20 22:39:16,833 - ERROR - [Errno 110] Connection timed out
2024-08-20 22:39:16,833 - ERROR - [Errno 110] Connection timed out
2024-08-20 22:39:16,833 - ERROR - [Errno 110] Connection timed out
2024-08-20 22:39:16,833 - ERROR - [Errno 110] Connection timed out
2024-08-20 22:39:16,833 - ERROR - [Errno 110] Connection timed out
2024-08-20 22:39:16,833 - ERROR - [Errno 110] Connection timed out
2024-08-20 22:39:16,833 - ERROR - Traceback (most recent call last):
  File "/home/donkami/Sona/devnet-candelaria/Services/InfraGeneral/interfaces_descriptions.py", line 25, in get_interfaces_descriptions
    client.connect(hostname=ip_switch, port=22, username='roadmin', password='C4nd3*2023')
  File "/home/donkami/.local/lib/python3.10/site-packages/paramiko/client.py", line 386, in connect
    sock.connect(addr)
TimeoutError: [Errno 110] Connection timed out

2024-08-20 22:39:16,833 - ERROR - Traceback (most recent call last):
  File "/home/donkami/Sona/devnet-candelaria/Services/InfraGeneral/interfaces_descriptions.py", line 25, in get_interfaces_descriptions
    client.connect(hostname=ip_switch, port=22, username='roadmin', password='C4nd3*2023')
  File "/home/donkami/.local/lib/python3.10/site-packages/paramiko/client.py", line 386, in connect
    sock.connect(addr)
TimeoutError: [Errno 110] Connection timed out

2024-08-20 22:39:16,833 - ERROR - Traceback (most recent call last):
  File "/home/donkami/Sona/devnet-candelaria/Services/InfraGeneral/interfaces_descriptions.py", line 25, in get_interfaces_descriptions
    client.connect(hostname=ip_switch, port=22, username='roadmin', password='C4nd3*2023')
  File "/home/donkami/.local/lib/python3.10/site-packages/paramiko/client.py", line 386, in connect
    sock.connect(addr)
TimeoutError: [Errno 110] Connection timed out

2024-08-20 22:39:16,833 - ERROR - Traceback (most recent call last):
  File "/home/donkami/Sona/devnet-candelaria/Services/InfraGeneral/interfaces_descriptions.py", line 25, in get_interfaces_descriptions
    client.connect(hostname=ip_switch, port=22, username='roadmin', password='C4nd3*2023')
  File "/home/donkami/.local/lib/python3.10/site-packages/paramiko/client.py", line 386, in connect
    sock.connect(addr)
TimeoutError: [Errno 110] Connection timed out

2024-08-20 22:39:16,833 - ERROR - Traceback (most recent call last):
  File "/home/donkami/Sona/devnet-candelaria/Services/InfraGeneral/interfaces_descriptions.py", line 25, in get_interfaces_descriptions
    client.connect(hostname=ip_switch, port=22, username='roadmin', password='C4nd3*2023')
  File "/home/donkami/.local/lib/python3.10/site-packages/paramiko/client.py", line 386, in connect
    sock.connect(addr)
TimeoutError: [Errno 110] Connection timed out

2024-08-20 22:39:16,833 - ERROR - Traceback (most recent call last):
  File "/home/donkami/Sona/devnet-candelaria/Services/InfraGeneral/interfaces_descriptions.py", line 25, in get_interfaces_descriptions
    client.connect(hostname=ip_switch, port=22, username='roadmin', password='C4nd3*2023')
  File "/home/donkami/.local/lib/python3.10/site-packages/paramiko/client.py", line 386, in connect
    sock.connect(addr)
TimeoutError: [Errno 110] Connection timed out

2024-08-20 22:39:16,833 - ERROR - Traceback (most recent call last):
  File "/home/donkami/Sona/devnet-candelaria/Services/InfraGeneral/interfaces_descriptions.py", line 25, in get_interfaces_descriptions
    client.connect(hostname=ip_switch, port=22, username='roadmin', password='C4nd3*2023')
  File "/home/donkami/.local/lib/python3.10/site-packages/paramiko/client.py", line 386, in connect
    sock.connect(addr)
TimeoutError: [Errno 110] Connection timed out

2024-08-20 22:41:29,951 - ERROR - Error en funcion INTERFACES DESCRIPTION
2024-08-20 22:41:29,951 - ERROR - Error en funcion INTERFACES DESCRIPTION
2024-08-20 22:41:29,951 - ERROR - Error en funcion INTERFACES DESCRIPTION
2024-08-20 22:41:29,951 - ERROR - Error en funcion INTERFACES DESCRIPTION
2024-08-20 22:41:29,951 - ERROR - Error en funcion INTERFACES DESCRIPTION
2024-08-20 22:41:29,951 - ERROR - Error en funcion INTERFACES DESCRIPTION
2024-08-20 22:41:29,951 - ERROR - Error en funcion INTERFACES DESCRIPTION
2024-08-20 22:41:29,951 - ERROR - [Errno 110] Connection timed out
2024-08-20 22:41:29,951 - ERROR - [Errno 110] Connection timed out
2024-08-20 22:41:29,951 - ERROR - [Errno 110] Connection timed out
2024-08-20 22:41:29,951 - ERROR - [Errno 110] Connection timed out
2024-08-20 22:41:29,951 - ERROR - [Errno 110] Connection timed out
2024-08-20 22:41:29,951 - ERROR - [Errno 110] Connection timed out
2024-08-20 22:41:29,951 - ERROR - [Errno 110] Connection timed out
2024-08-20 22:41:29,952 - ERROR - Traceback (most recent call last):
  File "/home/donkami/Sona/devnet-candelaria/Services/InfraGeneral/interfaces_descriptions.py", line 25, in get_interfaces_descriptions
    client.connect(hostname=ip_switch, port=22, username='roadmin', password='C4nd3*2023')
  File "/home/donkami/.local/lib/python3.10/site-packages/paramiko/client.py", line 386, in connect
    sock.connect(addr)
TimeoutError: [Errno 110] Connection timed out

2024-08-20 22:41:29,952 - ERROR - Traceback (most recent call last):
  File "/home/donkami/Sona/devnet-candelaria/Services/InfraGeneral/interfaces_descriptions.py", line 25, in get_interfaces_descriptions
    client.connect(hostname=ip_switch, port=22, username='roadmin', password='C4nd3*2023')
  File "/home/donkami/.local/lib/python3.10/site-packages/paramiko/client.py", line 386, in connect
    sock.connect(addr)
TimeoutError: [Errno 110] Connection timed out

2024-08-20 22:41:29,952 - ERROR - Traceback (most recent call last):
  File "/home/donkami/Sona/devnet-candelaria/Services/InfraGeneral/interfaces_descriptions.py", line 25, in get_interfaces_descriptions
    client.connect(hostname=ip_switch, port=22, username='roadmin', password='C4nd3*2023')
  File "/home/donkami/.local/lib/python3.10/site-packages/paramiko/client.py", line 386, in connect
    sock.connect(addr)
TimeoutError: [Errno 110] Connection timed out

2024-08-20 22:41:29,952 - ERROR - Traceback (most recent call last):
  File "/home/donkami/Sona/devnet-candelaria/Services/InfraGeneral/interfaces_descriptions.py", line 25, in get_interfaces_descriptions
    client.connect(hostname=ip_switch, port=22, username='roadmin', password='C4nd3*2023')
  File "/home/donkami/.local/lib/python3.10/site-packages/paramiko/client.py", line 386, in connect
    sock.connect(addr)
TimeoutError: [Errno 110] Connection timed out

2024-08-20 22:41:29,952 - ERROR - Traceback (most recent call last):
  File "/home/donkami/Sona/devnet-candelaria/Services/InfraGeneral/interfaces_descriptions.py", line 25, in get_interfaces_descriptions
    client.connect(hostname=ip_switch, port=22, username='roadmin', password='C4nd3*2023')
  File "/home/donkami/.local/lib/python3.10/site-packages/paramiko/client.py", line 386, in connect
    sock.connect(addr)
TimeoutError: [Errno 110] Connection timed out

2024-08-20 22:41:29,952 - ERROR - Traceback (most recent call last):
  File "/home/donkami/Sona/devnet-candelaria/Services/InfraGeneral/interfaces_descriptions.py", line 25, in get_interfaces_descriptions
    client.connect(hostname=ip_switch, port=22, username='roadmin', password='C4nd3*2023')
  File "/home/donkami/.local/lib/python3.10/site-packages/paramiko/client.py", line 386, in connect
    sock.connect(addr)
TimeoutError: [Errno 110] Connection timed out

2024-08-20 22:41:29,952 - ERROR - Traceback (most recent call last):
  File "/home/donkami/Sona/devnet-candelaria/Services/InfraGeneral/interfaces_descriptions.py", line 25, in get_interfaces_descriptions
    client.connect(hostname=ip_switch, port=22, username='roadmin', password='C4nd3*2023')
  File "/home/donkami/.local/lib/python3.10/site-packages/paramiko/client.py", line 386, in connect
    sock.connect(addr)
TimeoutError: [Errno 110] Connection timed out

2024-08-20 22:46:37,150 - ERROR - Error en funcion INTERFACES DESCRIPTION
2024-08-20 22:46:37,150 - ERROR - Error en funcion INTERFACES DESCRIPTION
2024-08-20 22:46:37,150 - ERROR - Error en funcion INTERFACES DESCRIPTION
2024-08-20 22:46:37,150 - ERROR - Error en funcion INTERFACES DESCRIPTION
2024-08-20 22:46:37,150 - ERROR - Error en funcion INTERFACES DESCRIPTION
2024-08-20 22:46:37,150 - ERROR - Error en funcion INTERFACES DESCRIPTION
2024-08-20 22:46:37,150 - ERROR - Error en funcion INTERFACES DESCRIPTION
2024-08-20 22:46:37,150 - ERROR - [Errno 110] Connection timed out
2024-08-20 22:46:37,150 - ERROR - [Errno 110] Connection timed out
2024-08-20 22:46:37,150 - ERROR - [Errno 110] Connection timed out
2024-08-20 22:46:37,150 - ERROR - [Errno 110] Connection timed out
2024-08-20 22:46:37,150 - ERROR - [Errno 110] Connection timed out
2024-08-20 22:46:37,150 - ERROR - [Errno 110] Connection timed out
2024-08-20 22:46:37,150 - ERROR - [Errno 110] Connection timed out
2024-08-20 22:46:37,151 - ERROR - Traceback (most recent call last):
  File "/home/donkami/Sona/devnet-candelaria/Services/InfraGeneral/interfaces_descriptions.py", line 25, in get_interfaces_descriptions
    client.connect(hostname=ip_switch, port=22, username='roadmin', password='C4nd3*2023')
  File "/home/donkami/.local/lib/python3.10/site-packages/paramiko/client.py", line 386, in connect
    sock.connect(addr)
TimeoutError: [Errno 110] Connection timed out

2024-08-20 22:46:37,151 - ERROR - Traceback (most recent call last):
  File "/home/donkami/Sona/devnet-candelaria/Services/InfraGeneral/interfaces_descriptions.py", line 25, in get_interfaces_descriptions
    client.connect(hostname=ip_switch, port=22, username='roadmin', password='C4nd3*2023')
  File "/home/donkami/.local/lib/python3.10/site-packages/paramiko/client.py", line 386, in connect
    sock.connect(addr)
TimeoutError: [Errno 110] Connection timed out

2024-08-20 22:46:37,151 - ERROR - Traceback (most recent call last):
  File "/home/donkami/Sona/devnet-candelaria/Services/InfraGeneral/interfaces_descriptions.py", line 25, in get_interfaces_descriptions
    client.connect(hostname=ip_switch, port=22, username='roadmin', password='C4nd3*2023')
  File "/home/donkami/.local/lib/python3.10/site-packages/paramiko/client.py", line 386, in connect
    sock.connect(addr)
TimeoutError: [Errno 110] Connection timed out

2024-08-20 22:46:37,151 - ERROR - Traceback (most recent call last):
  File "/home/donkami/Sona/devnet-candelaria/Services/InfraGeneral/interfaces_descriptions.py", line 25, in get_interfaces_descriptions
    client.connect(hostname=ip_switch, port=22, username='roadmin', password='C4nd3*2023')
  File "/home/donkami/.local/lib/python3.10/site-packages/paramiko/client.py", line 386, in connect
    sock.connect(addr)
TimeoutError: [Errno 110] Connection timed out

2024-08-20 22:46:37,151 - ERROR - Traceback (most recent call last):
  File "/home/donkami/Sona/devnet-candelaria/Services/InfraGeneral/interfaces_descriptions.py", line 25, in get_interfaces_descriptions
    client.connect(hostname=ip_switch, port=22, username='roadmin', password='C4nd3*2023')
  File "/home/donkami/.local/lib/python3.10/site-packages/paramiko/client.py", line 386, in connect
    sock.connect(addr)
TimeoutError: [Errno 110] Connection timed out

2024-08-20 22:46:37,151 - ERROR - Traceback (most recent call last):
  File "/home/donkami/Sona/devnet-candelaria/Services/InfraGeneral/interfaces_descriptions.py", line 25, in get_interfaces_descriptions
    client.connect(hostname=ip_switch, port=22, username='roadmin', password='C4nd3*2023')
  File "/home/donkami/.local/lib/python3.10/site-packages/paramiko/client.py", line 386, in connect
    sock.connect(addr)
TimeoutError: [Errno 110] Connection timed out

2024-08-20 22:46:37,151 - ERROR - Traceback (most recent call last):
  File "/home/donkami/Sona/devnet-candelaria/Services/InfraGeneral/interfaces_descriptions.py", line 25, in get_interfaces_descriptions
    client.connect(hostname=ip_switch, port=22, username='roadmin', password='C4nd3*2023')
  File "/home/donkami/.local/lib/python3.10/site-packages/paramiko/client.py", line 386, in connect
    sock.connect(addr)
TimeoutError: [Errno 110] Connection timed out

2024-08-20 22:48:50,269 - ERROR - Error en funcion INTERFACES DESCRIPTION
2024-08-20 22:48:50,269 - ERROR - Error en funcion INTERFACES DESCRIPTION
2024-08-20 22:48:50,269 - ERROR - Error en funcion INTERFACES DESCRIPTION
2024-08-20 22:48:50,269 - ERROR - Error en funcion INTERFACES DESCRIPTION
2024-08-20 22:48:50,269 - ERROR - Error en funcion INTERFACES DESCRIPTION
2024-08-20 22:48:50,269 - ERROR - Error en funcion INTERFACES DESCRIPTION
2024-08-20 22:48:50,269 - ERROR - Error en funcion INTERFACES DESCRIPTION
2024-08-20 22:48:50,270 - ERROR - [Errno 110] Connection timed out
2024-08-20 22:48:50,270 - ERROR - [Errno 110] Connection timed out
2024-08-20 22:48:50,270 - ERROR - [Errno 110] Connection timed out
2024-08-20 22:48:50,270 - ERROR - [Errno 110] Connection timed out
2024-08-20 22:48:50,270 - ERROR - [Errno 110] Connection timed out
2024-08-20 22:48:50,270 - ERROR - [Errno 110] Connection timed out
2024-08-20 22:48:50,270 - ERROR - [Errno 110] Connection timed out
2024-08-20 22:48:50,270 - ERROR - Traceback (most recent call last):
  File "/home/donkami/Sona/devnet-candelaria/Services/InfraGeneral/interfaces_descriptions.py", line 25, in get_interfaces_descriptions
    client.connect(hostname=ip_switch, port=22, username='roadmin', password='C4nd3*2023')
  File "/home/donkami/.local/lib/python3.10/site-packages/paramiko/client.py", line 386, in connect
    sock.connect(addr)
TimeoutError: [Errno 110] Connection timed out

2024-08-20 22:48:50,270 - ERROR - Traceback (most recent call last):
  File "/home/donkami/Sona/devnet-candelaria/Services/InfraGeneral/interfaces_descriptions.py", line 25, in get_interfaces_descriptions
    client.connect(hostname=ip_switch, port=22, username='roadmin', password='C4nd3*2023')
  File "/home/donkami/.local/lib/python3.10/site-packages/paramiko/client.py", line 386, in connect
    sock.connect(addr)
TimeoutError: [Errno 110] Connection timed out

2024-08-20 22:48:50,270 - ERROR - Traceback (most recent call last):
  File "/home/donkami/Sona/devnet-candelaria/Services/InfraGeneral/interfaces_descriptions.py", line 25, in get_interfaces_descriptions
    client.connect(hostname=ip_switch, port=22, username='roadmin', password='C4nd3*2023')
  File "/home/donkami/.local/lib/python3.10/site-packages/paramiko/client.py", line 386, in connect
    sock.connect(addr)
TimeoutError: [Errno 110] Connection timed out

2024-08-20 22:48:50,270 - ERROR - Traceback (most recent call last):
  File "/home/donkami/Sona/devnet-candelaria/Services/InfraGeneral/interfaces_descriptions.py", line 25, in get_interfaces_descriptions
    client.connect(hostname=ip_switch, port=22, username='roadmin', password='C4nd3*2023')
  File "/home/donkami/.local/lib/python3.10/site-packages/paramiko/client.py", line 386, in connect
    sock.connect(addr)
TimeoutError: [Errno 110] Connection timed out

2024-08-20 22:48:50,270 - ERROR - Traceback (most recent call last):
  File "/home/donkami/Sona/devnet-candelaria/Services/InfraGeneral/interfaces_descriptions.py", line 25, in get_interfaces_descriptions
    client.connect(hostname=ip_switch, port=22, username='roadmin', password='C4nd3*2023')
  File "/home/donkami/.local/lib/python3.10/site-packages/paramiko/client.py", line 386, in connect
    sock.connect(addr)
TimeoutError: [Errno 110] Connection timed out

2024-08-20 22:48:50,270 - ERROR - Traceback (most recent call last):
  File "/home/donkami/Sona/devnet-candelaria/Services/InfraGeneral/interfaces_descriptions.py", line 25, in get_interfaces_descriptions
    client.connect(hostname=ip_switch, port=22, username='roadmin', password='C4nd3*2023')
  File "/home/donkami/.local/lib/python3.10/site-packages/paramiko/client.py", line 386, in connect
    sock.connect(addr)
TimeoutError: [Errno 110] Connection timed out

2024-08-20 22:48:50,270 - ERROR - Traceback (most recent call last):
  File "/home/donkami/Sona/devnet-candelaria/Services/InfraGeneral/interfaces_descriptions.py", line 25, in get_interfaces_descriptions
    client.connect(hostname=ip_switch, port=22, username='roadmin', password='C4nd3*2023')
  File "/home/donkami/.local/lib/python3.10/site-packages/paramiko/client.py", line 386, in connect
    sock.connect(addr)
TimeoutError: [Errno 110] Connection timed out

2024-08-20 22:51:03,389 - ERROR - Error en funcion INTERFACES DESCRIPTION
2024-08-20 22:51:03,389 - ERROR - Error en funcion INTERFACES DESCRIPTION
2024-08-20 22:51:03,389 - ERROR - Error en funcion INTERFACES DESCRIPTION
2024-08-20 22:51:03,389 - ERROR - Error en funcion INTERFACES DESCRIPTION
2024-08-20 22:51:03,389 - ERROR - Error en funcion INTERFACES DESCRIPTION
2024-08-20 22:51:03,389 - ERROR - Error en funcion INTERFACES DESCRIPTION
2024-08-20 22:51:03,389 - ERROR - Error en funcion INTERFACES DESCRIPTION
2024-08-20 22:51:03,389 - ERROR - [Errno 110] Connection timed out
2024-08-20 22:51:03,389 - ERROR - [Errno 110] Connection timed out
2024-08-20 22:51:03,389 - ERROR - [Errno 110] Connection timed out
2024-08-20 22:51:03,389 - ERROR - [Errno 110] Connection timed out
2024-08-20 22:51:03,389 - ERROR - [Errno 110] Connection timed out
2024-08-20 22:51:03,389 - ERROR - [Errno 110] Connection timed out
2024-08-20 22:51:03,389 - ERROR - [Errno 110] Connection timed out
2024-08-20 22:51:03,390 - ERROR - Traceback (most recent call last):
  File "/home/donkami/Sona/devnet-candelaria/Services/InfraGeneral/interfaces_descriptions.py", line 25, in get_interfaces_descriptions
    client.connect(hostname=ip_switch, port=22, username='roadmin', password='C4nd3*2023')
  File "/home/donkami/.local/lib/python3.10/site-packages/paramiko/client.py", line 386, in connect
    sock.connect(addr)
TimeoutError: [Errno 110] Connection timed out

2024-08-20 22:51:03,390 - ERROR - Traceback (most recent call last):
  File "/home/donkami/Sona/devnet-candelaria/Services/InfraGeneral/interfaces_descriptions.py", line 25, in get_interfaces_descriptions
    client.connect(hostname=ip_switch, port=22, username='roadmin', password='C4nd3*2023')
  File "/home/donkami/.local/lib/python3.10/site-packages/paramiko/client.py", line 386, in connect
    sock.connect(addr)
TimeoutError: [Errno 110] Connection timed out

2024-08-20 22:51:03,390 - ERROR - Traceback (most recent call last):
  File "/home/donkami/Sona/devnet-candelaria/Services/InfraGeneral/interfaces_descriptions.py", line 25, in get_interfaces_descriptions
    client.connect(hostname=ip_switch, port=22, username='roadmin', password='C4nd3*2023')
  File "/home/donkami/.local/lib/python3.10/site-packages/paramiko/client.py", line 386, in connect
    sock.connect(addr)
TimeoutError: [Errno 110] Connection timed out

2024-08-20 22:51:03,390 - ERROR - Traceback (most recent call last):
  File "/home/donkami/Sona/devnet-candelaria/Services/InfraGeneral/interfaces_descriptions.py", line 25, in get_interfaces_descriptions
    client.connect(hostname=ip_switch, port=22, username='roadmin', password='C4nd3*2023')
  File "/home/donkami/.local/lib/python3.10/site-packages/paramiko/client.py", line 386, in connect
    sock.connect(addr)
TimeoutError: [Errno 110] Connection timed out

2024-08-20 22:51:03,390 - ERROR - Traceback (most recent call last):
  File "/home/donkami/Sona/devnet-candelaria/Services/InfraGeneral/interfaces_descriptions.py", line 25, in get_interfaces_descriptions
    client.connect(hostname=ip_switch, port=22, username='roadmin', password='C4nd3*2023')
  File "/home/donkami/.local/lib/python3.10/site-packages/paramiko/client.py", line 386, in connect
    sock.connect(addr)
TimeoutError: [Errno 110] Connection timed out

2024-08-20 22:51:03,390 - ERROR - Traceback (most recent call last):
  File "/home/donkami/Sona/devnet-candelaria/Services/InfraGeneral/interfaces_descriptions.py", line 25, in get_interfaces_descriptions
    client.connect(hostname=ip_switch, port=22, username='roadmin', password='C4nd3*2023')
  File "/home/donkami/.local/lib/python3.10/site-packages/paramiko/client.py", line 386, in connect
    sock.connect(addr)
TimeoutError: [Errno 110] Connection timed out

2024-08-20 22:51:03,390 - ERROR - Traceback (most recent call last):
  File "/home/donkami/Sona/devnet-candelaria/Services/InfraGeneral/interfaces_descriptions.py", line 25, in get_interfaces_descriptions
    client.connect(hostname=ip_switch, port=22, username='roadmin', password='C4nd3*2023')
  File "/home/donkami/.local/lib/python3.10/site-packages/paramiko/client.py", line 386, in connect
    sock.connect(addr)
TimeoutError: [Errno 110] Connection timed out

2024-08-20 22:53:16,509 - ERROR - Error en funcion INTERFACES DESCRIPTION
2024-08-20 22:53:16,509 - ERROR - Error en funcion INTERFACES DESCRIPTION
2024-08-20 22:53:16,509 - ERROR - Error en funcion INTERFACES DESCRIPTION
2024-08-20 22:53:16,509 - ERROR - Error en funcion INTERFACES DESCRIPTION
2024-08-20 22:53:16,509 - ERROR - Error en funcion INTERFACES DESCRIPTION
2024-08-20 22:53:16,509 - ERROR - Error en funcion INTERFACES DESCRIPTION
2024-08-20 22:53:16,509 - ERROR - Error en funcion INTERFACES DESCRIPTION
2024-08-20 22:53:16,509 - ERROR - [Errno 110] Connection timed out
2024-08-20 22:53:16,509 - ERROR - [Errno 110] Connection timed out
2024-08-20 22:53:16,509 - ERROR - [Errno 110] Connection timed out
2024-08-20 22:53:16,509 - ERROR - [Errno 110] Connection timed out
2024-08-20 22:53:16,509 - ERROR - [Errno 110] Connection timed out
2024-08-20 22:53:16,509 - ERROR - [Errno 110] Connection timed out
2024-08-20 22:53:16,509 - ERROR - [Errno 110] Connection timed out
2024-08-20 22:53:16,509 - ERROR - Traceback (most recent call last):
  File "/home/donkami/Sona/devnet-candelaria/Services/InfraGeneral/interfaces_descriptions.py", line 25, in get_interfaces_descriptions
    client.connect(hostname=ip_switch, port=22, username='roadmin', password='C4nd3*2023')
  File "/home/donkami/.local/lib/python3.10/site-packages/paramiko/client.py", line 386, in connect
    sock.connect(addr)
TimeoutError: [Errno 110] Connection timed out

2024-08-20 22:53:16,509 - ERROR - Traceback (most recent call last):
  File "/home/donkami/Sona/devnet-candelaria/Services/InfraGeneral/interfaces_descriptions.py", line 25, in get_interfaces_descriptions
    client.connect(hostname=ip_switch, port=22, username='roadmin', password='C4nd3*2023')
  File "/home/donkami/.local/lib/python3.10/site-packages/paramiko/client.py", line 386, in connect
    sock.connect(addr)
TimeoutError: [Errno 110] Connection timed out

2024-08-20 22:53:16,509 - ERROR - Traceback (most recent call last):
  File "/home/donkami/Sona/devnet-candelaria/Services/InfraGeneral/interfaces_descriptions.py", line 25, in get_interfaces_descriptions
    client.connect(hostname=ip_switch, port=22, username='roadmin', password='C4nd3*2023')
  File "/home/donkami/.local/lib/python3.10/site-packages/paramiko/client.py", line 386, in connect
    sock.connect(addr)
TimeoutError: [Errno 110] Connection timed out

2024-08-20 22:53:16,509 - ERROR - Traceback (most recent call last):
  File "/home/donkami/Sona/devnet-candelaria/Services/InfraGeneral/interfaces_descriptions.py", line 25, in get_interfaces_descriptions
    client.connect(hostname=ip_switch, port=22, username='roadmin', password='C4nd3*2023')
  File "/home/donkami/.local/lib/python3.10/site-packages/paramiko/client.py", line 386, in connect
    sock.connect(addr)
TimeoutError: [Errno 110] Connection timed out

2024-08-20 22:53:16,509 - ERROR - Traceback (most recent call last):
  File "/home/donkami/Sona/devnet-candelaria/Services/InfraGeneral/interfaces_descriptions.py", line 25, in get_interfaces_descriptions
    client.connect(hostname=ip_switch, port=22, username='roadmin', password='C4nd3*2023')
  File "/home/donkami/.local/lib/python3.10/site-packages/paramiko/client.py", line 386, in connect
    sock.connect(addr)
TimeoutError: [Errno 110] Connection timed out

2024-08-20 22:53:16,509 - ERROR - Traceback (most recent call last):
  File "/home/donkami/Sona/devnet-candelaria/Services/InfraGeneral/interfaces_descriptions.py", line 25, in get_interfaces_descriptions
    client.connect(hostname=ip_switch, port=22, username='roadmin', password='C4nd3*2023')
  File "/home/donkami/.local/lib/python3.10/site-packages/paramiko/client.py", line 386, in connect
    sock.connect(addr)
TimeoutError: [Errno 110] Connection timed out

2024-08-20 22:53:16,509 - ERROR - Traceback (most recent call last):
  File "/home/donkami/Sona/devnet-candelaria/Services/InfraGeneral/interfaces_descriptions.py", line 25, in get_interfaces_descriptions
    client.connect(hostname=ip_switch, port=22, username='roadmin', password='C4nd3*2023')
  File "/home/donkami/.local/lib/python3.10/site-packages/paramiko/client.py", line 386, in connect
    sock.connect(addr)
TimeoutError: [Errno 110] Connection timed out

2024-08-20 22:55:29,628 - ERROR - Error en funcion INTERFACES DESCRIPTION
2024-08-20 22:55:29,628 - ERROR - Error en funcion INTERFACES DESCRIPTION
2024-08-20 22:55:29,628 - ERROR - Error en funcion INTERFACES DESCRIPTION
2024-08-20 22:55:29,628 - ERROR - Error en funcion INTERFACES DESCRIPTION
2024-08-20 22:55:29,628 - ERROR - Error en funcion INTERFACES DESCRIPTION
2024-08-20 22:55:29,628 - ERROR - Error en funcion INTERFACES DESCRIPTION
2024-08-20 22:55:29,628 - ERROR - Error en funcion INTERFACES DESCRIPTION
2024-08-20 22:55:29,628 - ERROR - [Errno 110] Connection timed out
2024-08-20 22:55:29,628 - ERROR - [Errno 110] Connection timed out
2024-08-20 22:55:29,628 - ERROR - [Errno 110] Connection timed out
2024-08-20 22:55:29,628 - ERROR - [Errno 110] Connection timed out
2024-08-20 22:55:29,628 - ERROR - [Errno 110] Connection timed out
2024-08-20 22:55:29,628 - ERROR - [Errno 110] Connection timed out
2024-08-20 22:55:29,628 - ERROR - [Errno 110] Connection timed out
2024-08-20 22:55:29,629 - ERROR - Traceback (most recent call last):
  File "/home/donkami/Sona/devnet-candelaria/Services/InfraGeneral/interfaces_descriptions.py", line 25, in get_interfaces_descriptions
    client.connect(hostname=ip_switch, port=22, username='roadmin', password='C4nd3*2023')
  File "/home/donkami/.local/lib/python3.10/site-packages/paramiko/client.py", line 386, in connect
    sock.connect(addr)
TimeoutError: [Errno 110] Connection timed out

2024-08-20 22:55:29,629 - ERROR - Traceback (most recent call last):
  File "/home/donkami/Sona/devnet-candelaria/Services/InfraGeneral/interfaces_descriptions.py", line 25, in get_interfaces_descriptions
    client.connect(hostname=ip_switch, port=22, username='roadmin', password='C4nd3*2023')
  File "/home/donkami/.local/lib/python3.10/site-packages/paramiko/client.py", line 386, in connect
    sock.connect(addr)
TimeoutError: [Errno 110] Connection timed out

2024-08-20 22:55:29,629 - ERROR - Traceback (most recent call last):
  File "/home/donkami/Sona/devnet-candelaria/Services/InfraGeneral/interfaces_descriptions.py", line 25, in get_interfaces_descriptions
    client.connect(hostname=ip_switch, port=22, username='roadmin', password='C4nd3*2023')
  File "/home/donkami/.local/lib/python3.10/site-packages/paramiko/client.py", line 386, in connect
    sock.connect(addr)
TimeoutError: [Errno 110] Connection timed out

2024-08-20 22:55:29,629 - ERROR - Traceback (most recent call last):
  File "/home/donkami/Sona/devnet-candelaria/Services/InfraGeneral/interfaces_descriptions.py", line 25, in get_interfaces_descriptions
    client.connect(hostname=ip_switch, port=22, username='roadmin', password='C4nd3*2023')
  File "/home/donkami/.local/lib/python3.10/site-packages/paramiko/client.py", line 386, in connect
    sock.connect(addr)
TimeoutError: [Errno 110] Connection timed out

2024-08-20 22:55:29,629 - ERROR - Traceback (most recent call last):
  File "/home/donkami/Sona/devnet-candelaria/Services/InfraGeneral/interfaces_descriptions.py", line 25, in get_interfaces_descriptions
    client.connect(hostname=ip_switch, port=22, username='roadmin', password='C4nd3*2023')
  File "/home/donkami/.local/lib/python3.10/site-packages/paramiko/client.py", line 386, in connect
    sock.connect(addr)
TimeoutError: [Errno 110] Connection timed out

2024-08-20 22:55:29,629 - ERROR - Traceback (most recent call last):
  File "/home/donkami/Sona/devnet-candelaria/Services/InfraGeneral/interfaces_descriptions.py", line 25, in get_interfaces_descriptions
    client.connect(hostname=ip_switch, port=22, username='roadmin', password='C4nd3*2023')
  File "/home/donkami/.local/lib/python3.10/site-packages/paramiko/client.py", line 386, in connect
    sock.connect(addr)
TimeoutError: [Errno 110] Connection timed out

2024-08-20 22:55:29,629 - ERROR - Traceback (most recent call last):
  File "/home/donkami/Sona/devnet-candelaria/Services/InfraGeneral/interfaces_descriptions.py", line 25, in get_interfaces_descriptions
    client.connect(hostname=ip_switch, port=22, username='roadmin', password='C4nd3*2023')
  File "/home/donkami/.local/lib/python3.10/site-packages/paramiko/client.py", line 386, in connect
    sock.connect(addr)
TimeoutError: [Errno 110] Connection timed out

2024-08-21 09:30:27,469 - ERROR - Error en funcion INTERFACES DESCRIPTION
2024-08-21 09:30:27,469 - ERROR - Error en funcion INTERFACES DESCRIPTION
2024-08-21 09:30:27,469 - ERROR - Error en funcion INTERFACES DESCRIPTION
2024-08-21 09:30:27,469 - ERROR - Error en funcion INTERFACES DESCRIPTION
2024-08-21 09:30:27,469 - ERROR - Error en funcion INTERFACES DESCRIPTION
2024-08-21 09:30:27,469 - ERROR - Error en funcion INTERFACES DESCRIPTION
2024-08-21 09:30:27,469 - ERROR - Error en funcion INTERFACES DESCRIPTION
2024-08-21 09:30:27,479 - ERROR - [Errno 110] Connection timed out
2024-08-21 09:30:27,479 - ERROR - [Errno 110] Connection timed out
2024-08-21 09:30:27,479 - ERROR - [Errno 110] Connection timed out
2024-08-21 09:30:27,479 - ERROR - [Errno 110] Connection timed out
2024-08-21 09:30:27,479 - ERROR - [Errno 110] Connection timed out
2024-08-21 09:30:27,479 - ERROR - [Errno 110] Connection timed out
2024-08-21 09:30:27,479 - ERROR - [Errno 110] Connection timed out
2024-08-21 09:30:27,481 - ERROR - Traceback (most recent call last):
  File "/home/donkami/Sona/devnet-candelaria/Services/InfraGeneral/interfaces_descriptions.py", line 25, in get_interfaces_descriptions
    client.connect(hostname=ip_switch, port=22, username='roadmin', password='C4nd3*2023')
  File "/home/donkami/.local/lib/python3.10/site-packages/paramiko/client.py", line 386, in connect
    sock.connect(addr)
TimeoutError: [Errno 110] Connection timed out

2024-08-21 09:30:27,481 - ERROR - Traceback (most recent call last):
  File "/home/donkami/Sona/devnet-candelaria/Services/InfraGeneral/interfaces_descriptions.py", line 25, in get_interfaces_descriptions
    client.connect(hostname=ip_switch, port=22, username='roadmin', password='C4nd3*2023')
  File "/home/donkami/.local/lib/python3.10/site-packages/paramiko/client.py", line 386, in connect
    sock.connect(addr)
TimeoutError: [Errno 110] Connection timed out

2024-08-21 09:30:27,481 - ERROR - Traceback (most recent call last):
  File "/home/donkami/Sona/devnet-candelaria/Services/InfraGeneral/interfaces_descriptions.py", line 25, in get_interfaces_descriptions
    client.connect(hostname=ip_switch, port=22, username='roadmin', password='C4nd3*2023')
  File "/home/donkami/.local/lib/python3.10/site-packages/paramiko/client.py", line 386, in connect
    sock.connect(addr)
TimeoutError: [Errno 110] Connection timed out

2024-08-21 09:30:27,481 - ERROR - Traceback (most recent call last):
  File "/home/donkami/Sona/devnet-candelaria/Services/InfraGeneral/interfaces_descriptions.py", line 25, in get_interfaces_descriptions
    client.connect(hostname=ip_switch, port=22, username='roadmin', password='C4nd3*2023')
  File "/home/donkami/.local/lib/python3.10/site-packages/paramiko/client.py", line 386, in connect
    sock.connect(addr)
TimeoutError: [Errno 110] Connection timed out

2024-08-21 09:30:27,481 - ERROR - Traceback (most recent call last):
  File "/home/donkami/Sona/devnet-candelaria/Services/InfraGeneral/interfaces_descriptions.py", line 25, in get_interfaces_descriptions
    client.connect(hostname=ip_switch, port=22, username='roadmin', password='C4nd3*2023')
  File "/home/donkami/.local/lib/python3.10/site-packages/paramiko/client.py", line 386, in connect
    sock.connect(addr)
TimeoutError: [Errno 110] Connection timed out

2024-08-21 09:30:27,481 - ERROR - Traceback (most recent call last):
  File "/home/donkami/Sona/devnet-candelaria/Services/InfraGeneral/interfaces_descriptions.py", line 25, in get_interfaces_descriptions
    client.connect(hostname=ip_switch, port=22, username='roadmin', password='C4nd3*2023')
  File "/home/donkami/.local/lib/python3.10/site-packages/paramiko/client.py", line 386, in connect
    sock.connect(addr)
TimeoutError: [Errno 110] Connection timed out

2024-08-21 09:30:27,481 - ERROR - Traceback (most recent call last):
  File "/home/donkami/Sona/devnet-candelaria/Services/InfraGeneral/interfaces_descriptions.py", line 25, in get_interfaces_descriptions
    client.connect(hostname=ip_switch, port=22, username='roadmin', password='C4nd3*2023')
  File "/home/donkami/.local/lib/python3.10/site-packages/paramiko/client.py", line 386, in connect
    sock.connect(addr)
TimeoutError: [Errno 110] Connection timed out

2024-08-21 09:32:40,589 - ERROR - Error en funcion INTERFACES DESCRIPTION
2024-08-21 09:32:40,589 - ERROR - Error en funcion INTERFACES DESCRIPTION
2024-08-21 09:32:40,589 - ERROR - Error en funcion INTERFACES DESCRIPTION
2024-08-21 09:32:40,589 - ERROR - Error en funcion INTERFACES DESCRIPTION
2024-08-21 09:32:40,589 - ERROR - Error en funcion INTERFACES DESCRIPTION
2024-08-21 09:32:40,589 - ERROR - Error en funcion INTERFACES DESCRIPTION
2024-08-21 09:32:40,589 - ERROR - Error en funcion INTERFACES DESCRIPTION
2024-08-21 09:32:40,589 - ERROR - [Errno 110] Connection timed out
2024-08-21 09:32:40,589 - ERROR - [Errno 110] Connection timed out
2024-08-21 09:32:40,589 - ERROR - [Errno 110] Connection timed out
2024-08-21 09:32:40,589 - ERROR - [Errno 110] Connection timed out
2024-08-21 09:32:40,589 - ERROR - [Errno 110] Connection timed out
2024-08-21 09:32:40,589 - ERROR - [Errno 110] Connection timed out
2024-08-21 09:32:40,589 - ERROR - [Errno 110] Connection timed out
2024-08-21 09:32:40,590 - ERROR - Traceback (most recent call last):
  File "/home/donkami/Sona/devnet-candelaria/Services/InfraGeneral/interfaces_descriptions.py", line 25, in get_interfaces_descriptions
    client.connect(hostname=ip_switch, port=22, username='roadmin', password='C4nd3*2023')
  File "/home/donkami/.local/lib/python3.10/site-packages/paramiko/client.py", line 386, in connect
    sock.connect(addr)
TimeoutError: [Errno 110] Connection timed out

2024-08-21 09:32:40,590 - ERROR - Traceback (most recent call last):
  File "/home/donkami/Sona/devnet-candelaria/Services/InfraGeneral/interfaces_descriptions.py", line 25, in get_interfaces_descriptions
    client.connect(hostname=ip_switch, port=22, username='roadmin', password='C4nd3*2023')
  File "/home/donkami/.local/lib/python3.10/site-packages/paramiko/client.py", line 386, in connect
    sock.connect(addr)
TimeoutError: [Errno 110] Connection timed out

2024-08-21 09:32:40,590 - ERROR - Traceback (most recent call last):
  File "/home/donkami/Sona/devnet-candelaria/Services/InfraGeneral/interfaces_descriptions.py", line 25, in get_interfaces_descriptions
    client.connect(hostname=ip_switch, port=22, username='roadmin', password='C4nd3*2023')
  File "/home/donkami/.local/lib/python3.10/site-packages/paramiko/client.py", line 386, in connect
    sock.connect(addr)
TimeoutError: [Errno 110] Connection timed out

2024-08-21 09:32:40,590 - ERROR - Traceback (most recent call last):
  File "/home/donkami/Sona/devnet-candelaria/Services/InfraGeneral/interfaces_descriptions.py", line 25, in get_interfaces_descriptions
    client.connect(hostname=ip_switch, port=22, username='roadmin', password='C4nd3*2023')
  File "/home/donkami/.local/lib/python3.10/site-packages/paramiko/client.py", line 386, in connect
    sock.connect(addr)
TimeoutError: [Errno 110] Connection timed out

2024-08-21 09:32:40,590 - ERROR - Traceback (most recent call last):
  File "/home/donkami/Sona/devnet-candelaria/Services/InfraGeneral/interfaces_descriptions.py", line 25, in get_interfaces_descriptions
    client.connect(hostname=ip_switch, port=22, username='roadmin', password='C4nd3*2023')
  File "/home/donkami/.local/lib/python3.10/site-packages/paramiko/client.py", line 386, in connect
    sock.connect(addr)
TimeoutError: [Errno 110] Connection timed out

2024-08-21 09:32:40,590 - ERROR - Traceback (most recent call last):
  File "/home/donkami/Sona/devnet-candelaria/Services/InfraGeneral/interfaces_descriptions.py", line 25, in get_interfaces_descriptions
    client.connect(hostname=ip_switch, port=22, username='roadmin', password='C4nd3*2023')
  File "/home/donkami/.local/lib/python3.10/site-packages/paramiko/client.py", line 386, in connect
    sock.connect(addr)
TimeoutError: [Errno 110] Connection timed out

2024-08-21 09:32:40,590 - ERROR - Traceback (most recent call last):
  File "/home/donkami/Sona/devnet-candelaria/Services/InfraGeneral/interfaces_descriptions.py", line 25, in get_interfaces_descriptions
    client.connect(hostname=ip_switch, port=22, username='roadmin', password='C4nd3*2023')
  File "/home/donkami/.local/lib/python3.10/site-packages/paramiko/client.py", line 386, in connect
    sock.connect(addr)
TimeoutError: [Errno 110] Connection timed out

2024-08-21 09:34:53,708 - ERROR - Error en funcion INTERFACES DESCRIPTION
2024-08-21 09:34:53,708 - ERROR - Error en funcion INTERFACES DESCRIPTION
2024-08-21 09:34:53,708 - ERROR - Error en funcion INTERFACES DESCRIPTION
2024-08-21 09:34:53,708 - ERROR - Error en funcion INTERFACES DESCRIPTION
2024-08-21 09:34:53,708 - ERROR - Error en funcion INTERFACES DESCRIPTION
2024-08-21 09:34:53,708 - ERROR - Error en funcion INTERFACES DESCRIPTION
2024-08-21 09:34:53,708 - ERROR - Error en funcion INTERFACES DESCRIPTION
2024-08-21 09:34:53,709 - ERROR - [Errno 110] Connection timed out
2024-08-21 09:34:53,709 - ERROR - [Errno 110] Connection timed out
2024-08-21 09:34:53,709 - ERROR - [Errno 110] Connection timed out
2024-08-21 09:34:53,709 - ERROR - [Errno 110] Connection timed out
2024-08-21 09:34:53,709 - ERROR - [Errno 110] Connection timed out
2024-08-21 09:34:53,709 - ERROR - [Errno 110] Connection timed out
2024-08-21 09:34:53,709 - ERROR - [Errno 110] Connection timed out
2024-08-21 09:34:53,709 - ERROR - Traceback (most recent call last):
  File "/home/donkami/Sona/devnet-candelaria/Services/InfraGeneral/interfaces_descriptions.py", line 25, in get_interfaces_descriptions
    client.connect(hostname=ip_switch, port=22, username='roadmin', password='C4nd3*2023')
  File "/home/donkami/.local/lib/python3.10/site-packages/paramiko/client.py", line 386, in connect
    sock.connect(addr)
TimeoutError: [Errno 110] Connection timed out

2024-08-21 09:34:53,709 - ERROR - Traceback (most recent call last):
  File "/home/donkami/Sona/devnet-candelaria/Services/InfraGeneral/interfaces_descriptions.py", line 25, in get_interfaces_descriptions
    client.connect(hostname=ip_switch, port=22, username='roadmin', password='C4nd3*2023')
  File "/home/donkami/.local/lib/python3.10/site-packages/paramiko/client.py", line 386, in connect
    sock.connect(addr)
TimeoutError: [Errno 110] Connection timed out

2024-08-21 09:34:53,709 - ERROR - Traceback (most recent call last):
  File "/home/donkami/Sona/devnet-candelaria/Services/InfraGeneral/interfaces_descriptions.py", line 25, in get_interfaces_descriptions
    client.connect(hostname=ip_switch, port=22, username='roadmin', password='C4nd3*2023')
  File "/home/donkami/.local/lib/python3.10/site-packages/paramiko/client.py", line 386, in connect
    sock.connect(addr)
TimeoutError: [Errno 110] Connection timed out

2024-08-21 09:34:53,709 - ERROR - Traceback (most recent call last):
  File "/home/donkami/Sona/devnet-candelaria/Services/InfraGeneral/interfaces_descriptions.py", line 25, in get_interfaces_descriptions
    client.connect(hostname=ip_switch, port=22, username='roadmin', password='C4nd3*2023')
  File "/home/donkami/.local/lib/python3.10/site-packages/paramiko/client.py", line 386, in connect
    sock.connect(addr)
TimeoutError: [Errno 110] Connection timed out

2024-08-21 09:34:53,709 - ERROR - Traceback (most recent call last):
  File "/home/donkami/Sona/devnet-candelaria/Services/InfraGeneral/interfaces_descriptions.py", line 25, in get_interfaces_descriptions
    client.connect(hostname=ip_switch, port=22, username='roadmin', password='C4nd3*2023')
  File "/home/donkami/.local/lib/python3.10/site-packages/paramiko/client.py", line 386, in connect
    sock.connect(addr)
TimeoutError: [Errno 110] Connection timed out

2024-08-21 09:34:53,709 - ERROR - Traceback (most recent call last):
  File "/home/donkami/Sona/devnet-candelaria/Services/InfraGeneral/interfaces_descriptions.py", line 25, in get_interfaces_descriptions
    client.connect(hostname=ip_switch, port=22, username='roadmin', password='C4nd3*2023')
  File "/home/donkami/.local/lib/python3.10/site-packages/paramiko/client.py", line 386, in connect
    sock.connect(addr)
TimeoutError: [Errno 110] Connection timed out

2024-08-21 09:34:53,709 - ERROR - Traceback (most recent call last):
  File "/home/donkami/Sona/devnet-candelaria/Services/InfraGeneral/interfaces_descriptions.py", line 25, in get_interfaces_descriptions
    client.connect(hostname=ip_switch, port=22, username='roadmin', password='C4nd3*2023')
  File "/home/donkami/.local/lib/python3.10/site-packages/paramiko/client.py", line 386, in connect
    sock.connect(addr)
TimeoutError: [Errno 110] Connection timed out

2024-08-21 09:37:06,828 - ERROR - Error en funcion INTERFACES DESCRIPTION
2024-08-21 09:37:06,828 - ERROR - Error en funcion INTERFACES DESCRIPTION
2024-08-21 09:37:06,828 - ERROR - Error en funcion INTERFACES DESCRIPTION
2024-08-21 09:37:06,828 - ERROR - Error en funcion INTERFACES DESCRIPTION
2024-08-21 09:37:06,828 - ERROR - Error en funcion INTERFACES DESCRIPTION
2024-08-21 09:37:06,828 - ERROR - Error en funcion INTERFACES DESCRIPTION
2024-08-21 09:37:06,828 - ERROR - Error en funcion INTERFACES DESCRIPTION
2024-08-21 09:37:06,829 - ERROR - [Errno 110] Connection timed out
2024-08-21 09:37:06,829 - ERROR - [Errno 110] Connection timed out
2024-08-21 09:37:06,829 - ERROR - [Errno 110] Connection timed out
2024-08-21 09:37:06,829 - ERROR - [Errno 110] Connection timed out
2024-08-21 09:37:06,829 - ERROR - [Errno 110] Connection timed out
2024-08-21 09:37:06,829 - ERROR - [Errno 110] Connection timed out
2024-08-21 09:37:06,829 - ERROR - [Errno 110] Connection timed out
2024-08-21 09:37:06,829 - ERROR - Traceback (most recent call last):
  File "/home/donkami/Sona/devnet-candelaria/Services/InfraGeneral/interfaces_descriptions.py", line 25, in get_interfaces_descriptions
    client.connect(hostname=ip_switch, port=22, username='roadmin', password='C4nd3*2023')
  File "/home/donkami/.local/lib/python3.10/site-packages/paramiko/client.py", line 386, in connect
    sock.connect(addr)
TimeoutError: [Errno 110] Connection timed out

2024-08-21 09:37:06,829 - ERROR - Traceback (most recent call last):
  File "/home/donkami/Sona/devnet-candelaria/Services/InfraGeneral/interfaces_descriptions.py", line 25, in get_interfaces_descriptions
    client.connect(hostname=ip_switch, port=22, username='roadmin', password='C4nd3*2023')
  File "/home/donkami/.local/lib/python3.10/site-packages/paramiko/client.py", line 386, in connect
    sock.connect(addr)
TimeoutError: [Errno 110] Connection timed out

2024-08-21 09:37:06,829 - ERROR - Traceback (most recent call last):
  File "/home/donkami/Sona/devnet-candelaria/Services/InfraGeneral/interfaces_descriptions.py", line 25, in get_interfaces_descriptions
    client.connect(hostname=ip_switch, port=22, username='roadmin', password='C4nd3*2023')
  File "/home/donkami/.local/lib/python3.10/site-packages/paramiko/client.py", line 386, in connect
    sock.connect(addr)
TimeoutError: [Errno 110] Connection timed out

2024-08-21 09:37:06,829 - ERROR - Traceback (most recent call last):
  File "/home/donkami/Sona/devnet-candelaria/Services/InfraGeneral/interfaces_descriptions.py", line 25, in get_interfaces_descriptions
    client.connect(hostname=ip_switch, port=22, username='roadmin', password='C4nd3*2023')
  File "/home/donkami/.local/lib/python3.10/site-packages/paramiko/client.py", line 386, in connect
    sock.connect(addr)
TimeoutError: [Errno 110] Connection timed out

2024-08-21 09:37:06,829 - ERROR - Traceback (most recent call last):
  File "/home/donkami/Sona/devnet-candelaria/Services/InfraGeneral/interfaces_descriptions.py", line 25, in get_interfaces_descriptions
    client.connect(hostname=ip_switch, port=22, username='roadmin', password='C4nd3*2023')
  File "/home/donkami/.local/lib/python3.10/site-packages/paramiko/client.py", line 386, in connect
    sock.connect(addr)
TimeoutError: [Errno 110] Connection timed out

2024-08-21 09:37:06,829 - ERROR - Traceback (most recent call last):
  File "/home/donkami/Sona/devnet-candelaria/Services/InfraGeneral/interfaces_descriptions.py", line 25, in get_interfaces_descriptions
    client.connect(hostname=ip_switch, port=22, username='roadmin', password='C4nd3*2023')
  File "/home/donkami/.local/lib/python3.10/site-packages/paramiko/client.py", line 386, in connect
    sock.connect(addr)
TimeoutError: [Errno 110] Connection timed out

2024-08-21 09:37:06,829 - ERROR - Traceback (most recent call last):
  File "/home/donkami/Sona/devnet-candelaria/Services/InfraGeneral/interfaces_descriptions.py", line 25, in get_interfaces_descriptions
    client.connect(hostname=ip_switch, port=22, username='roadmin', password='C4nd3*2023')
  File "/home/donkami/.local/lib/python3.10/site-packages/paramiko/client.py", line 386, in connect
    sock.connect(addr)
TimeoutError: [Errno 110] Connection timed out

2024-08-21 09:39:19,948 - ERROR - Error en funcion INTERFACES DESCRIPTION
2024-08-21 09:39:19,948 - ERROR - Error en funcion INTERFACES DESCRIPTION
2024-08-21 09:39:19,948 - ERROR - Error en funcion INTERFACES DESCRIPTION
2024-08-21 09:39:19,948 - ERROR - Error en funcion INTERFACES DESCRIPTION
2024-08-21 09:39:19,948 - ERROR - Error en funcion INTERFACES DESCRIPTION
2024-08-21 09:39:19,948 - ERROR - Error en funcion INTERFACES DESCRIPTION
2024-08-21 09:39:19,948 - ERROR - Error en funcion INTERFACES DESCRIPTION
2024-08-21 09:39:19,948 - ERROR - [Errno 110] Connection timed out
2024-08-21 09:39:19,948 - ERROR - [Errno 110] Connection timed out
2024-08-21 09:39:19,948 - ERROR - [Errno 110] Connection timed out
2024-08-21 09:39:19,948 - ERROR - [Errno 110] Connection timed out
2024-08-21 09:39:19,948 - ERROR - [Errno 110] Connection timed out
2024-08-21 09:39:19,948 - ERROR - [Errno 110] Connection timed out
2024-08-21 09:39:19,948 - ERROR - [Errno 110] Connection timed out
2024-08-21 09:39:19,948 - ERROR - Traceback (most recent call last):
  File "/home/donkami/Sona/devnet-candelaria/Services/InfraGeneral/interfaces_descriptions.py", line 25, in get_interfaces_descriptions
    client.connect(hostname=ip_switch, port=22, username='roadmin', password='C4nd3*2023')
  File "/home/donkami/.local/lib/python3.10/site-packages/paramiko/client.py", line 386, in connect
    sock.connect(addr)
TimeoutError: [Errno 110] Connection timed out

2024-08-21 09:39:19,948 - ERROR - Traceback (most recent call last):
  File "/home/donkami/Sona/devnet-candelaria/Services/InfraGeneral/interfaces_descriptions.py", line 25, in get_interfaces_descriptions
    client.connect(hostname=ip_switch, port=22, username='roadmin', password='C4nd3*2023')
  File "/home/donkami/.local/lib/python3.10/site-packages/paramiko/client.py", line 386, in connect
    sock.connect(addr)
TimeoutError: [Errno 110] Connection timed out

2024-08-21 09:39:19,948 - ERROR - Traceback (most recent call last):
  File "/home/donkami/Sona/devnet-candelaria/Services/InfraGeneral/interfaces_descriptions.py", line 25, in get_interfaces_descriptions
    client.connect(hostname=ip_switch, port=22, username='roadmin', password='C4nd3*2023')
  File "/home/donkami/.local/lib/python3.10/site-packages/paramiko/client.py", line 386, in connect
    sock.connect(addr)
TimeoutError: [Errno 110] Connection timed out

2024-08-21 09:39:19,948 - ERROR - Traceback (most recent call last):
  File "/home/donkami/Sona/devnet-candelaria/Services/InfraGeneral/interfaces_descriptions.py", line 25, in get_interfaces_descriptions
    client.connect(hostname=ip_switch, port=22, username='roadmin', password='C4nd3*2023')
  File "/home/donkami/.local/lib/python3.10/site-packages/paramiko/client.py", line 386, in connect
    sock.connect(addr)
TimeoutError: [Errno 110] Connection timed out

2024-08-21 09:39:19,948 - ERROR - Traceback (most recent call last):
  File "/home/donkami/Sona/devnet-candelaria/Services/InfraGeneral/interfaces_descriptions.py", line 25, in get_interfaces_descriptions
    client.connect(hostname=ip_switch, port=22, username='roadmin', password='C4nd3*2023')
  File "/home/donkami/.local/lib/python3.10/site-packages/paramiko/client.py", line 386, in connect
    sock.connect(addr)
TimeoutError: [Errno 110] Connection timed out

2024-08-21 09:39:19,948 - ERROR - Traceback (most recent call last):
  File "/home/donkami/Sona/devnet-candelaria/Services/InfraGeneral/interfaces_descriptions.py", line 25, in get_interfaces_descriptions
    client.connect(hostname=ip_switch, port=22, username='roadmin', password='C4nd3*2023')
  File "/home/donkami/.local/lib/python3.10/site-packages/paramiko/client.py", line 386, in connect
    sock.connect(addr)
TimeoutError: [Errno 110] Connection timed out

2024-08-21 09:39:19,948 - ERROR - Traceback (most recent call last):
  File "/home/donkami/Sona/devnet-candelaria/Services/InfraGeneral/interfaces_descriptions.py", line 25, in get_interfaces_descriptions
    client.connect(hostname=ip_switch, port=22, username='roadmin', password='C4nd3*2023')
  File "/home/donkami/.local/lib/python3.10/site-packages/paramiko/client.py", line 386, in connect
    sock.connect(addr)
TimeoutError: [Errno 110] Connection timed out

2024-08-21 19:21:07,920 - ERROR - Traceback (most recent call last):
  File "/home/donkami/.local/lib/python3.10/site-packages/urllib3/connection.py", line 200, in _new_conn
    sock = connection.create_connection(
  File "/home/donkami/.local/lib/python3.10/site-packages/urllib3/util/connection.py", line 85, in create_connection
    raise err
  File "/home/donkami/.local/lib/python3.10/site-packages/urllib3/util/connection.py", line 73, in create_connection
    sock.connect(sa)
TimeoutError: [Errno 110] Connection timed out

The above exception was the direct cause of the following exception:

Traceback (most recent call last):
  File "/home/donkami/.local/lib/python3.10/site-packages/urllib3/connectionpool.py", line 790, in urlopen
    response = self._make_request(
  File "/home/donkami/.local/lib/python3.10/site-packages/urllib3/connectionpool.py", line 491, in _make_request
    raise new_e
  File "/home/donkami/.local/lib/python3.10/site-packages/urllib3/connectionpool.py", line 467, in _make_request
    self._validate_conn(conn)
  File "/home/donkami/.local/lib/python3.10/site-packages/urllib3/connectionpool.py", line 1092, in _validate_conn
    conn.connect()
  File "/home/donkami/.local/lib/python3.10/site-packages/urllib3/connection.py", line 604, in connect
    self.sock = sock = self._new_conn()
  File "/home/donkami/.local/lib/python3.10/site-packages/urllib3/connection.py", line 209, in _new_conn
    raise ConnectTimeoutError(
urllib3.exceptions.ConnectTimeoutError: (<urllib3.connection.HTTPSConnection object at 0x7f88f2692950>, 'Connection to 10.224.241.25 timed out. (connect timeout=None)')

The above exception was the direct cause of the following exception:

Traceback (most recent call last):
  File "/home/donkami/.local/lib/python3.10/site-packages/requests/adapters.py", line 486, in send
    resp = conn.urlopen(
  File "/home/donkami/.local/lib/python3.10/site-packages/urllib3/connectionpool.py", line 844, in urlopen
    retries = retries.increment(
  File "/home/donkami/.local/lib/python3.10/site-packages/urllib3/util/retry.py", line 515, in increment
    raise MaxRetryError(_pool, url, reason) from reason  # type: ignore[arg-type]
urllib3.exceptions.MaxRetryError: HTTPSConnectionPool(host='10.224.241.25', port=443): Max retries exceeded with url: /api/table.json?content=devices&columns=objid&filter_host=172.31.1.244&username=canadmin&password=Carrera01&count=* (Caused by ConnectTimeoutError(<urllib3.connection.HTTPSConnection object at 0x7f88f2692950>, 'Connection to 10.224.241.25 timed out. (connect timeout=None)'))

During handling of the above exception, another exception occurred:

Traceback (most recent call last):
  File "/home/donkami/Sona/devnet-candelaria/Services/InfraGeneral/main.py", line 87, in core1
    id_prtg_switch = get_id_prtg(ip_switch)
  File "/home/donkami/Sona/devnet-candelaria/Services/InfraGeneral/main.py", line 248, in get_id_prtg
    response_objid = requests.get(url_objid, verify=False).json()
  File "/home/donkami/.local/lib/python3.10/site-packages/requests/api.py", line 73, in get
    return request("get", url, params=params, **kwargs)
  File "/home/donkami/.local/lib/python3.10/site-packages/requests/api.py", line 59, in request
    return session.request(method=method, url=url, **kwargs)
  File "/home/donkami/.local/lib/python3.10/site-packages/requests/sessions.py", line 589, in request
    resp = self.send(prep, **send_kwargs)
  File "/home/donkami/.local/lib/python3.10/site-packages/requests/sessions.py", line 703, in send
    r = adapter.send(request, **kwargs)
  File "/home/donkami/.local/lib/python3.10/site-packages/requests/adapters.py", line 507, in send
    raise ConnectTimeout(e, request=request)
requests.exceptions.ConnectTimeout: HTTPSConnectionPool(host='10.224.241.25', port=443): Max retries exceeded with url: /api/table.json?content=devices&columns=objid&filter_host=172.31.1.244&username=canadmin&password=Carrera01&count=* (Caused by ConnectTimeoutError(<urllib3.connection.HTTPSConnection object at 0x7f88f2692950>, 'Connection to 10.224.241.25 timed out. (connect timeout=None)'))

2024-08-21 19:21:07,920 - ERROR - Traceback (most recent call last):
  File "/home/donkami/.local/lib/python3.10/site-packages/urllib3/connection.py", line 200, in _new_conn
    sock = connection.create_connection(
  File "/home/donkami/.local/lib/python3.10/site-packages/urllib3/util/connection.py", line 85, in create_connection
    raise err
  File "/home/donkami/.local/lib/python3.10/site-packages/urllib3/util/connection.py", line 73, in create_connection
    sock.connect(sa)
TimeoutError: [Errno 110] Connection timed out

The above exception was the direct cause of the following exception:

Traceback (most recent call last):
  File "/home/donkami/.local/lib/python3.10/site-packages/urllib3/connectionpool.py", line 790, in urlopen
    response = self._make_request(
  File "/home/donkami/.local/lib/python3.10/site-packages/urllib3/connectionpool.py", line 491, in _make_request
    raise new_e
  File "/home/donkami/.local/lib/python3.10/site-packages/urllib3/connectionpool.py", line 467, in _make_request
    self._validate_conn(conn)
  File "/home/donkami/.local/lib/python3.10/site-packages/urllib3/connectionpool.py", line 1092, in _validate_conn
    conn.connect()
  File "/home/donkami/.local/lib/python3.10/site-packages/urllib3/connection.py", line 604, in connect
    self.sock = sock = self._new_conn()
  File "/home/donkami/.local/lib/python3.10/site-packages/urllib3/connection.py", line 209, in _new_conn
    raise ConnectTimeoutError(
urllib3.exceptions.ConnectTimeoutError: (<urllib3.connection.HTTPSConnection object at 0x7f88f2692950>, 'Connection to 10.224.241.25 timed out. (connect timeout=None)')

The above exception was the direct cause of the following exception:

Traceback (most recent call last):
  File "/home/donkami/.local/lib/python3.10/site-packages/requests/adapters.py", line 486, in send
    resp = conn.urlopen(
  File "/home/donkami/.local/lib/python3.10/site-packages/urllib3/connectionpool.py", line 844, in urlopen
    retries = retries.increment(
  File "/home/donkami/.local/lib/python3.10/site-packages/urllib3/util/retry.py", line 515, in increment
    raise MaxRetryError(_pool, url, reason) from reason  # type: ignore[arg-type]
urllib3.exceptions.MaxRetryError: HTTPSConnectionPool(host='10.224.241.25', port=443): Max retries exceeded with url: /api/table.json?content=devices&columns=objid&filter_host=172.31.1.244&username=canadmin&password=Carrera01&count=* (Caused by ConnectTimeoutError(<urllib3.connection.HTTPSConnection object at 0x7f88f2692950>, 'Connection to 10.224.241.25 timed out. (connect timeout=None)'))

During handling of the above exception, another exception occurred:

Traceback (most recent call last):
  File "/home/donkami/Sona/devnet-candelaria/Services/InfraGeneral/main.py", line 87, in core1
    id_prtg_switch = get_id_prtg(ip_switch)
  File "/home/donkami/Sona/devnet-candelaria/Services/InfraGeneral/main.py", line 248, in get_id_prtg
    response_objid = requests.get(url_objid, verify=False).json()
  File "/home/donkami/.local/lib/python3.10/site-packages/requests/api.py", line 73, in get
    return request("get", url, params=params, **kwargs)
  File "/home/donkami/.local/lib/python3.10/site-packages/requests/api.py", line 59, in request
    return session.request(method=method, url=url, **kwargs)
  File "/home/donkami/.local/lib/python3.10/site-packages/requests/sessions.py", line 589, in request
    resp = self.send(prep, **send_kwargs)
  File "/home/donkami/.local/lib/python3.10/site-packages/requests/sessions.py", line 703, in send
    r = adapter.send(request, **kwargs)
  File "/home/donkami/.local/lib/python3.10/site-packages/requests/adapters.py", line 507, in send
    raise ConnectTimeout(e, request=request)
requests.exceptions.ConnectTimeout: HTTPSConnectionPool(host='10.224.241.25', port=443): Max retries exceeded with url: /api/table.json?content=devices&columns=objid&filter_host=172.31.1.244&username=canadmin&password=Carrera01&count=* (Caused by ConnectTimeoutError(<urllib3.connection.HTTPSConnection object at 0x7f88f2692950>, 'Connection to 10.224.241.25 timed out. (connect timeout=None)'))

2024-08-21 19:21:07,920 - ERROR - Traceback (most recent call last):
  File "/home/donkami/.local/lib/python3.10/site-packages/urllib3/connection.py", line 200, in _new_conn
    sock = connection.create_connection(
  File "/home/donkami/.local/lib/python3.10/site-packages/urllib3/util/connection.py", line 85, in create_connection
    raise err
  File "/home/donkami/.local/lib/python3.10/site-packages/urllib3/util/connection.py", line 73, in create_connection
    sock.connect(sa)
TimeoutError: [Errno 110] Connection timed out

The above exception was the direct cause of the following exception:

Traceback (most recent call last):
  File "/home/donkami/.local/lib/python3.10/site-packages/urllib3/connectionpool.py", line 790, in urlopen
    response = self._make_request(
  File "/home/donkami/.local/lib/python3.10/site-packages/urllib3/connectionpool.py", line 491, in _make_request
    raise new_e
  File "/home/donkami/.local/lib/python3.10/site-packages/urllib3/connectionpool.py", line 467, in _make_request
    self._validate_conn(conn)
  File "/home/donkami/.local/lib/python3.10/site-packages/urllib3/connectionpool.py", line 1092, in _validate_conn
    conn.connect()
  File "/home/donkami/.local/lib/python3.10/site-packages/urllib3/connection.py", line 604, in connect
    self.sock = sock = self._new_conn()
  File "/home/donkami/.local/lib/python3.10/site-packages/urllib3/connection.py", line 209, in _new_conn
    raise ConnectTimeoutError(
urllib3.exceptions.ConnectTimeoutError: (<urllib3.connection.HTTPSConnection object at 0x7f88f2692950>, 'Connection to 10.224.241.25 timed out. (connect timeout=None)')

The above exception was the direct cause of the following exception:

Traceback (most recent call last):
  File "/home/donkami/.local/lib/python3.10/site-packages/requests/adapters.py", line 486, in send
    resp = conn.urlopen(
  File "/home/donkami/.local/lib/python3.10/site-packages/urllib3/connectionpool.py", line 844, in urlopen
    retries = retries.increment(
  File "/home/donkami/.local/lib/python3.10/site-packages/urllib3/util/retry.py", line 515, in increment
    raise MaxRetryError(_pool, url, reason) from reason  # type: ignore[arg-type]
urllib3.exceptions.MaxRetryError: HTTPSConnectionPool(host='10.224.241.25', port=443): Max retries exceeded with url: /api/table.json?content=devices&columns=objid&filter_host=172.31.1.244&username=canadmin&password=Carrera01&count=* (Caused by ConnectTimeoutError(<urllib3.connection.HTTPSConnection object at 0x7f88f2692950>, 'Connection to 10.224.241.25 timed out. (connect timeout=None)'))

During handling of the above exception, another exception occurred:

Traceback (most recent call last):
  File "/home/donkami/Sona/devnet-candelaria/Services/InfraGeneral/main.py", line 87, in core1
    id_prtg_switch = get_id_prtg(ip_switch)
  File "/home/donkami/Sona/devnet-candelaria/Services/InfraGeneral/main.py", line 248, in get_id_prtg
    response_objid = requests.get(url_objid, verify=False).json()
  File "/home/donkami/.local/lib/python3.10/site-packages/requests/api.py", line 73, in get
    return request("get", url, params=params, **kwargs)
  File "/home/donkami/.local/lib/python3.10/site-packages/requests/api.py", line 59, in request
    return session.request(method=method, url=url, **kwargs)
  File "/home/donkami/.local/lib/python3.10/site-packages/requests/sessions.py", line 589, in request
    resp = self.send(prep, **send_kwargs)
  File "/home/donkami/.local/lib/python3.10/site-packages/requests/sessions.py", line 703, in send
    r = adapter.send(request, **kwargs)
  File "/home/donkami/.local/lib/python3.10/site-packages/requests/adapters.py", line 507, in send
    raise ConnectTimeout(e, request=request)
requests.exceptions.ConnectTimeout: HTTPSConnectionPool(host='10.224.241.25', port=443): Max retries exceeded with url: /api/table.json?content=devices&columns=objid&filter_host=172.31.1.244&username=canadmin&password=Carrera01&count=* (Caused by ConnectTimeoutError(<urllib3.connection.HTTPSConnection object at 0x7f88f2692950>, 'Connection to 10.224.241.25 timed out. (connect timeout=None)'))

2024-08-21 19:21:07,920 - ERROR - Traceback (most recent call last):
  File "/home/donkami/.local/lib/python3.10/site-packages/urllib3/connection.py", line 200, in _new_conn
    sock = connection.create_connection(
  File "/home/donkami/.local/lib/python3.10/site-packages/urllib3/util/connection.py", line 85, in create_connection
    raise err
  File "/home/donkami/.local/lib/python3.10/site-packages/urllib3/util/connection.py", line 73, in create_connection
    sock.connect(sa)
TimeoutError: [Errno 110] Connection timed out

The above exception was the direct cause of the following exception:

Traceback (most recent call last):
  File "/home/donkami/.local/lib/python3.10/site-packages/urllib3/connectionpool.py", line 790, in urlopen
    response = self._make_request(
  File "/home/donkami/.local/lib/python3.10/site-packages/urllib3/connectionpool.py", line 491, in _make_request
    raise new_e
  File "/home/donkami/.local/lib/python3.10/site-packages/urllib3/connectionpool.py", line 467, in _make_request
    self._validate_conn(conn)
  File "/home/donkami/.local/lib/python3.10/site-packages/urllib3/connectionpool.py", line 1092, in _validate_conn
    conn.connect()
  File "/home/donkami/.local/lib/python3.10/site-packages/urllib3/connection.py", line 604, in connect
    self.sock = sock = self._new_conn()
  File "/home/donkami/.local/lib/python3.10/site-packages/urllib3/connection.py", line 209, in _new_conn
    raise ConnectTimeoutError(
urllib3.exceptions.ConnectTimeoutError: (<urllib3.connection.HTTPSConnection object at 0x7f88f2692950>, 'Connection to 10.224.241.25 timed out. (connect timeout=None)')

The above exception was the direct cause of the following exception:

Traceback (most recent call last):
  File "/home/donkami/.local/lib/python3.10/site-packages/requests/adapters.py", line 486, in send
    resp = conn.urlopen(
  File "/home/donkami/.local/lib/python3.10/site-packages/urllib3/connectionpool.py", line 844, in urlopen
    retries = retries.increment(
  File "/home/donkami/.local/lib/python3.10/site-packages/urllib3/util/retry.py", line 515, in increment
    raise MaxRetryError(_pool, url, reason) from reason  # type: ignore[arg-type]
urllib3.exceptions.MaxRetryError: HTTPSConnectionPool(host='10.224.241.25', port=443): Max retries exceeded with url: /api/table.json?content=devices&columns=objid&filter_host=172.31.1.244&username=canadmin&password=Carrera01&count=* (Caused by ConnectTimeoutError(<urllib3.connection.HTTPSConnection object at 0x7f88f2692950>, 'Connection to 10.224.241.25 timed out. (connect timeout=None)'))

During handling of the above exception, another exception occurred:

Traceback (most recent call last):
  File "/home/donkami/Sona/devnet-candelaria/Services/InfraGeneral/main.py", line 87, in core1
    id_prtg_switch = get_id_prtg(ip_switch)
  File "/home/donkami/Sona/devnet-candelaria/Services/InfraGeneral/main.py", line 248, in get_id_prtg
    response_objid = requests.get(url_objid, verify=False).json()
  File "/home/donkami/.local/lib/python3.10/site-packages/requests/api.py", line 73, in get
    return request("get", url, params=params, **kwargs)
  File "/home/donkami/.local/lib/python3.10/site-packages/requests/api.py", line 59, in request
    return session.request(method=method, url=url, **kwargs)
  File "/home/donkami/.local/lib/python3.10/site-packages/requests/sessions.py", line 589, in request
    resp = self.send(prep, **send_kwargs)
  File "/home/donkami/.local/lib/python3.10/site-packages/requests/sessions.py", line 703, in send
    r = adapter.send(request, **kwargs)
  File "/home/donkami/.local/lib/python3.10/site-packages/requests/adapters.py", line 507, in send
    raise ConnectTimeout(e, request=request)
requests.exceptions.ConnectTimeout: HTTPSConnectionPool(host='10.224.241.25', port=443): Max retries exceeded with url: /api/table.json?content=devices&columns=objid&filter_host=172.31.1.244&username=canadmin&password=Carrera01&count=* (Caused by ConnectTimeoutError(<urllib3.connection.HTTPSConnection object at 0x7f88f2692950>, 'Connection to 10.224.241.25 timed out. (connect timeout=None)'))

2024-08-21 19:21:07,920 - ERROR - Traceback (most recent call last):
  File "/home/donkami/.local/lib/python3.10/site-packages/urllib3/connection.py", line 200, in _new_conn
    sock = connection.create_connection(
  File "/home/donkami/.local/lib/python3.10/site-packages/urllib3/util/connection.py", line 85, in create_connection
    raise err
  File "/home/donkami/.local/lib/python3.10/site-packages/urllib3/util/connection.py", line 73, in create_connection
    sock.connect(sa)
TimeoutError: [Errno 110] Connection timed out

The above exception was the direct cause of the following exception:

Traceback (most recent call last):
  File "/home/donkami/.local/lib/python3.10/site-packages/urllib3/connectionpool.py", line 790, in urlopen
    response = self._make_request(
  File "/home/donkami/.local/lib/python3.10/site-packages/urllib3/connectionpool.py", line 491, in _make_request
    raise new_e
  File "/home/donkami/.local/lib/python3.10/site-packages/urllib3/connectionpool.py", line 467, in _make_request
    self._validate_conn(conn)
  File "/home/donkami/.local/lib/python3.10/site-packages/urllib3/connectionpool.py", line 1092, in _validate_conn
    conn.connect()
  File "/home/donkami/.local/lib/python3.10/site-packages/urllib3/connection.py", line 604, in connect
    self.sock = sock = self._new_conn()
  File "/home/donkami/.local/lib/python3.10/site-packages/urllib3/connection.py", line 209, in _new_conn
    raise ConnectTimeoutError(
urllib3.exceptions.ConnectTimeoutError: (<urllib3.connection.HTTPSConnection object at 0x7f88f2692950>, 'Connection to 10.224.241.25 timed out. (connect timeout=None)')

The above exception was the direct cause of the following exception:

Traceback (most recent call last):
  File "/home/donkami/.local/lib/python3.10/site-packages/requests/adapters.py", line 486, in send
    resp = conn.urlopen(
  File "/home/donkami/.local/lib/python3.10/site-packages/urllib3/connectionpool.py", line 844, in urlopen
    retries = retries.increment(
  File "/home/donkami/.local/lib/python3.10/site-packages/urllib3/util/retry.py", line 515, in increment
    raise MaxRetryError(_pool, url, reason) from reason  # type: ignore[arg-type]
urllib3.exceptions.MaxRetryError: HTTPSConnectionPool(host='10.224.241.25', port=443): Max retries exceeded with url: /api/table.json?content=devices&columns=objid&filter_host=172.31.1.244&username=canadmin&password=Carrera01&count=* (Caused by ConnectTimeoutError(<urllib3.connection.HTTPSConnection object at 0x7f88f2692950>, 'Connection to 10.224.241.25 timed out. (connect timeout=None)'))

During handling of the above exception, another exception occurred:

Traceback (most recent call last):
  File "/home/donkami/Sona/devnet-candelaria/Services/InfraGeneral/main.py", line 87, in core1
    id_prtg_switch = get_id_prtg(ip_switch)
  File "/home/donkami/Sona/devnet-candelaria/Services/InfraGeneral/main.py", line 248, in get_id_prtg
    response_objid = requests.get(url_objid, verify=False).json()
  File "/home/donkami/.local/lib/python3.10/site-packages/requests/api.py", line 73, in get
    return request("get", url, params=params, **kwargs)
  File "/home/donkami/.local/lib/python3.10/site-packages/requests/api.py", line 59, in request
    return session.request(method=method, url=url, **kwargs)
  File "/home/donkami/.local/lib/python3.10/site-packages/requests/sessions.py", line 589, in request
    resp = self.send(prep, **send_kwargs)
  File "/home/donkami/.local/lib/python3.10/site-packages/requests/sessions.py", line 703, in send
    r = adapter.send(request, **kwargs)
  File "/home/donkami/.local/lib/python3.10/site-packages/requests/adapters.py", line 507, in send
    raise ConnectTimeout(e, request=request)
requests.exceptions.ConnectTimeout: HTTPSConnectionPool(host='10.224.241.25', port=443): Max retries exceeded with url: /api/table.json?content=devices&columns=objid&filter_host=172.31.1.244&username=canadmin&password=Carrera01&count=* (Caused by ConnectTimeoutError(<urllib3.connection.HTTPSConnection object at 0x7f88f2692950>, 'Connection to 10.224.241.25 timed out. (connect timeout=None)'))

2024-08-21 19:21:07,920 - ERROR - Traceback (most recent call last):
  File "/home/donkami/.local/lib/python3.10/site-packages/urllib3/connection.py", line 200, in _new_conn
    sock = connection.create_connection(
  File "/home/donkami/.local/lib/python3.10/site-packages/urllib3/util/connection.py", line 85, in create_connection
    raise err
  File "/home/donkami/.local/lib/python3.10/site-packages/urllib3/util/connection.py", line 73, in create_connection
    sock.connect(sa)
TimeoutError: [Errno 110] Connection timed out

The above exception was the direct cause of the following exception:

Traceback (most recent call last):
  File "/home/donkami/.local/lib/python3.10/site-packages/urllib3/connectionpool.py", line 790, in urlopen
    response = self._make_request(
  File "/home/donkami/.local/lib/python3.10/site-packages/urllib3/connectionpool.py", line 491, in _make_request
    raise new_e
  File "/home/donkami/.local/lib/python3.10/site-packages/urllib3/connectionpool.py", line 467, in _make_request
    self._validate_conn(conn)
  File "/home/donkami/.local/lib/python3.10/site-packages/urllib3/connectionpool.py", line 1092, in _validate_conn
    conn.connect()
  File "/home/donkami/.local/lib/python3.10/site-packages/urllib3/connection.py", line 604, in connect
    self.sock = sock = self._new_conn()
  File "/home/donkami/.local/lib/python3.10/site-packages/urllib3/connection.py", line 209, in _new_conn
    raise ConnectTimeoutError(
urllib3.exceptions.ConnectTimeoutError: (<urllib3.connection.HTTPSConnection object at 0x7f88f2692950>, 'Connection to 10.224.241.25 timed out. (connect timeout=None)')

The above exception was the direct cause of the following exception:

Traceback (most recent call last):
  File "/home/donkami/.local/lib/python3.10/site-packages/requests/adapters.py", line 486, in send
    resp = conn.urlopen(
  File "/home/donkami/.local/lib/python3.10/site-packages/urllib3/connectionpool.py", line 844, in urlopen
    retries = retries.increment(
  File "/home/donkami/.local/lib/python3.10/site-packages/urllib3/util/retry.py", line 515, in increment
    raise MaxRetryError(_pool, url, reason) from reason  # type: ignore[arg-type]
urllib3.exceptions.MaxRetryError: HTTPSConnectionPool(host='10.224.241.25', port=443): Max retries exceeded with url: /api/table.json?content=devices&columns=objid&filter_host=172.31.1.244&username=canadmin&password=Carrera01&count=* (Caused by ConnectTimeoutError(<urllib3.connection.HTTPSConnection object at 0x7f88f2692950>, 'Connection to 10.224.241.25 timed out. (connect timeout=None)'))

During handling of the above exception, another exception occurred:

Traceback (most recent call last):
  File "/home/donkami/Sona/devnet-candelaria/Services/InfraGeneral/main.py", line 87, in core1
    id_prtg_switch = get_id_prtg(ip_switch)
  File "/home/donkami/Sona/devnet-candelaria/Services/InfraGeneral/main.py", line 248, in get_id_prtg
    response_objid = requests.get(url_objid, verify=False).json()
  File "/home/donkami/.local/lib/python3.10/site-packages/requests/api.py", line 73, in get
    return request("get", url, params=params, **kwargs)
  File "/home/donkami/.local/lib/python3.10/site-packages/requests/api.py", line 59, in request
    return session.request(method=method, url=url, **kwargs)
  File "/home/donkami/.local/lib/python3.10/site-packages/requests/sessions.py", line 589, in request
    resp = self.send(prep, **send_kwargs)
  File "/home/donkami/.local/lib/python3.10/site-packages/requests/sessions.py", line 703, in send
    r = adapter.send(request, **kwargs)
  File "/home/donkami/.local/lib/python3.10/site-packages/requests/adapters.py", line 507, in send
    raise ConnectTimeout(e, request=request)
requests.exceptions.ConnectTimeout: HTTPSConnectionPool(host='10.224.241.25', port=443): Max retries exceeded with url: /api/table.json?content=devices&columns=objid&filter_host=172.31.1.244&username=canadmin&password=Carrera01&count=* (Caused by ConnectTimeoutError(<urllib3.connection.HTTPSConnection object at 0x7f88f2692950>, 'Connection to 10.224.241.25 timed out. (connect timeout=None)'))

2024-08-21 19:21:07,920 - ERROR - Traceback (most recent call last):
  File "/home/donkami/.local/lib/python3.10/site-packages/urllib3/connection.py", line 200, in _new_conn
    sock = connection.create_connection(
  File "/home/donkami/.local/lib/python3.10/site-packages/urllib3/util/connection.py", line 85, in create_connection
    raise err
  File "/home/donkami/.local/lib/python3.10/site-packages/urllib3/util/connection.py", line 73, in create_connection
    sock.connect(sa)
TimeoutError: [Errno 110] Connection timed out

The above exception was the direct cause of the following exception:

Traceback (most recent call last):
  File "/home/donkami/.local/lib/python3.10/site-packages/urllib3/connectionpool.py", line 790, in urlopen
    response = self._make_request(
  File "/home/donkami/.local/lib/python3.10/site-packages/urllib3/connectionpool.py", line 491, in _make_request
    raise new_e
  File "/home/donkami/.local/lib/python3.10/site-packages/urllib3/connectionpool.py", line 467, in _make_request
    self._validate_conn(conn)
  File "/home/donkami/.local/lib/python3.10/site-packages/urllib3/connectionpool.py", line 1092, in _validate_conn
    conn.connect()
  File "/home/donkami/.local/lib/python3.10/site-packages/urllib3/connection.py", line 604, in connect
    self.sock = sock = self._new_conn()
  File "/home/donkami/.local/lib/python3.10/site-packages/urllib3/connection.py", line 209, in _new_conn
    raise ConnectTimeoutError(
urllib3.exceptions.ConnectTimeoutError: (<urllib3.connection.HTTPSConnection object at 0x7f88f2692950>, 'Connection to 10.224.241.25 timed out. (connect timeout=None)')

The above exception was the direct cause of the following exception:

Traceback (most recent call last):
  File "/home/donkami/.local/lib/python3.10/site-packages/requests/adapters.py", line 486, in send
    resp = conn.urlopen(
  File "/home/donkami/.local/lib/python3.10/site-packages/urllib3/connectionpool.py", line 844, in urlopen
    retries = retries.increment(
  File "/home/donkami/.local/lib/python3.10/site-packages/urllib3/util/retry.py", line 515, in increment
    raise MaxRetryError(_pool, url, reason) from reason  # type: ignore[arg-type]
urllib3.exceptions.MaxRetryError: HTTPSConnectionPool(host='10.224.241.25', port=443): Max retries exceeded with url: /api/table.json?content=devices&columns=objid&filter_host=172.31.1.244&username=canadmin&password=Carrera01&count=* (Caused by ConnectTimeoutError(<urllib3.connection.HTTPSConnection object at 0x7f88f2692950>, 'Connection to 10.224.241.25 timed out. (connect timeout=None)'))

During handling of the above exception, another exception occurred:

Traceback (most recent call last):
  File "/home/donkami/Sona/devnet-candelaria/Services/InfraGeneral/main.py", line 87, in core1
    id_prtg_switch = get_id_prtg(ip_switch)
  File "/home/donkami/Sona/devnet-candelaria/Services/InfraGeneral/main.py", line 248, in get_id_prtg
    response_objid = requests.get(url_objid, verify=False).json()
  File "/home/donkami/.local/lib/python3.10/site-packages/requests/api.py", line 73, in get
    return request("get", url, params=params, **kwargs)
  File "/home/donkami/.local/lib/python3.10/site-packages/requests/api.py", line 59, in request
    return session.request(method=method, url=url, **kwargs)
  File "/home/donkami/.local/lib/python3.10/site-packages/requests/sessions.py", line 589, in request
    resp = self.send(prep, **send_kwargs)
  File "/home/donkami/.local/lib/python3.10/site-packages/requests/sessions.py", line 703, in send
    r = adapter.send(request, **kwargs)
  File "/home/donkami/.local/lib/python3.10/site-packages/requests/adapters.py", line 507, in send
    raise ConnectTimeout(e, request=request)
requests.exceptions.ConnectTimeout: HTTPSConnectionPool(host='10.224.241.25', port=443): Max retries exceeded with url: /api/table.json?content=devices&columns=objid&filter_host=172.31.1.244&username=canadmin&password=Carrera01&count=* (Caused by ConnectTimeoutError(<urllib3.connection.HTTPSConnection object at 0x7f88f2692950>, 'Connection to 10.224.241.25 timed out. (connect timeout=None)'))

2024-08-21 21:23:28,386 - ERROR - Traceback (most recent call last):
  File "/home/donkami/.local/lib/python3.10/site-packages/urllib3/connection.py", line 200, in _new_conn
    sock = connection.create_connection(
  File "/home/donkami/.local/lib/python3.10/site-packages/urllib3/util/connection.py", line 85, in create_connection
    raise err
  File "/home/donkami/.local/lib/python3.10/site-packages/urllib3/util/connection.py", line 73, in create_connection
    sock.connect(sa)
TimeoutError: [Errno 110] Connection timed out

The above exception was the direct cause of the following exception:

Traceback (most recent call last):
  File "/home/donkami/.local/lib/python3.10/site-packages/urllib3/connectionpool.py", line 790, in urlopen
    response = self._make_request(
  File "/home/donkami/.local/lib/python3.10/site-packages/urllib3/connectionpool.py", line 491, in _make_request
    raise new_e
  File "/home/donkami/.local/lib/python3.10/site-packages/urllib3/connectionpool.py", line 467, in _make_request
    self._validate_conn(conn)
  File "/home/donkami/.local/lib/python3.10/site-packages/urllib3/connectionpool.py", line 1092, in _validate_conn
    conn.connect()
  File "/home/donkami/.local/lib/python3.10/site-packages/urllib3/connection.py", line 604, in connect
    self.sock = sock = self._new_conn()
  File "/home/donkami/.local/lib/python3.10/site-packages/urllib3/connection.py", line 209, in _new_conn
    raise ConnectTimeoutError(
urllib3.exceptions.ConnectTimeoutError: (<urllib3.connection.HTTPSConnection object at 0x7f88f26919f0>, 'Connection to 10.224.241.25 timed out. (connect timeout=None)')

The above exception was the direct cause of the following exception:

Traceback (most recent call last):
  File "/home/donkami/.local/lib/python3.10/site-packages/requests/adapters.py", line 486, in send
    resp = conn.urlopen(
  File "/home/donkami/.local/lib/python3.10/site-packages/urllib3/connectionpool.py", line 844, in urlopen
    retries = retries.increment(
  File "/home/donkami/.local/lib/python3.10/site-packages/urllib3/util/retry.py", line 515, in increment
    raise MaxRetryError(_pool, url, reason) from reason  # type: ignore[arg-type]
urllib3.exceptions.MaxRetryError: HTTPSConnectionPool(host='10.224.241.25', port=443): Max retries exceeded with url: /api/table.json?content=devices&columns=objid&filter_host=10.224.127.1&username=canadmin&password=Carrera01&count=* (Caused by ConnectTimeoutError(<urllib3.connection.HTTPSConnection object at 0x7f88f26919f0>, 'Connection to 10.224.241.25 timed out. (connect timeout=None)'))

During handling of the above exception, another exception occurred:

Traceback (most recent call last):
  File "/home/donkami/Sona/devnet-candelaria/Services/InfraGeneral/main.py", line 87, in core1
    id_prtg_switch = get_id_prtg(ip_switch)
  File "/home/donkami/Sona/devnet-candelaria/Services/InfraGeneral/main.py", line 248, in get_id_prtg
    response_objid = requests.get(url_objid, verify=False).json()
  File "/home/donkami/.local/lib/python3.10/site-packages/requests/api.py", line 73, in get
    return request("get", url, params=params, **kwargs)
  File "/home/donkami/.local/lib/python3.10/site-packages/requests/api.py", line 59, in request
    return session.request(method=method, url=url, **kwargs)
  File "/home/donkami/.local/lib/python3.10/site-packages/requests/sessions.py", line 589, in request
    resp = self.send(prep, **send_kwargs)
  File "/home/donkami/.local/lib/python3.10/site-packages/requests/sessions.py", line 703, in send
    r = adapter.send(request, **kwargs)
  File "/home/donkami/.local/lib/python3.10/site-packages/requests/adapters.py", line 507, in send
    raise ConnectTimeout(e, request=request)
requests.exceptions.ConnectTimeout: HTTPSConnectionPool(host='10.224.241.25', port=443): Max retries exceeded with url: /api/table.json?content=devices&columns=objid&filter_host=10.224.127.1&username=canadmin&password=Carrera01&count=* (Caused by ConnectTimeoutError(<urllib3.connection.HTTPSConnection object at 0x7f88f26919f0>, 'Connection to 10.224.241.25 timed out. (connect timeout=None)'))

2024-08-21 21:23:28,386 - ERROR - Traceback (most recent call last):
  File "/home/donkami/.local/lib/python3.10/site-packages/urllib3/connection.py", line 200, in _new_conn
    sock = connection.create_connection(
  File "/home/donkami/.local/lib/python3.10/site-packages/urllib3/util/connection.py", line 85, in create_connection
    raise err
  File "/home/donkami/.local/lib/python3.10/site-packages/urllib3/util/connection.py", line 73, in create_connection
    sock.connect(sa)
TimeoutError: [Errno 110] Connection timed out

The above exception was the direct cause of the following exception:

Traceback (most recent call last):
  File "/home/donkami/.local/lib/python3.10/site-packages/urllib3/connectionpool.py", line 790, in urlopen
    response = self._make_request(
  File "/home/donkami/.local/lib/python3.10/site-packages/urllib3/connectionpool.py", line 491, in _make_request
    raise new_e
  File "/home/donkami/.local/lib/python3.10/site-packages/urllib3/connectionpool.py", line 467, in _make_request
    self._validate_conn(conn)
  File "/home/donkami/.local/lib/python3.10/site-packages/urllib3/connectionpool.py", line 1092, in _validate_conn
    conn.connect()
  File "/home/donkami/.local/lib/python3.10/site-packages/urllib3/connection.py", line 604, in connect
    self.sock = sock = self._new_conn()
  File "/home/donkami/.local/lib/python3.10/site-packages/urllib3/connection.py", line 209, in _new_conn
    raise ConnectTimeoutError(
urllib3.exceptions.ConnectTimeoutError: (<urllib3.connection.HTTPSConnection object at 0x7f88f26919f0>, 'Connection to 10.224.241.25 timed out. (connect timeout=None)')

The above exception was the direct cause of the following exception:

Traceback (most recent call last):
  File "/home/donkami/.local/lib/python3.10/site-packages/requests/adapters.py", line 486, in send
    resp = conn.urlopen(
  File "/home/donkami/.local/lib/python3.10/site-packages/urllib3/connectionpool.py", line 844, in urlopen
    retries = retries.increment(
  File "/home/donkami/.local/lib/python3.10/site-packages/urllib3/util/retry.py", line 515, in increment
    raise MaxRetryError(_pool, url, reason) from reason  # type: ignore[arg-type]
urllib3.exceptions.MaxRetryError: HTTPSConnectionPool(host='10.224.241.25', port=443): Max retries exceeded with url: /api/table.json?content=devices&columns=objid&filter_host=10.224.127.1&username=canadmin&password=Carrera01&count=* (Caused by ConnectTimeoutError(<urllib3.connection.HTTPSConnection object at 0x7f88f26919f0>, 'Connection to 10.224.241.25 timed out. (connect timeout=None)'))

During handling of the above exception, another exception occurred:

Traceback (most recent call last):
  File "/home/donkami/Sona/devnet-candelaria/Services/InfraGeneral/main.py", line 87, in core1
    id_prtg_switch = get_id_prtg(ip_switch)
  File "/home/donkami/Sona/devnet-candelaria/Services/InfraGeneral/main.py", line 248, in get_id_prtg
    response_objid = requests.get(url_objid, verify=False).json()
  File "/home/donkami/.local/lib/python3.10/site-packages/requests/api.py", line 73, in get
    return request("get", url, params=params, **kwargs)
  File "/home/donkami/.local/lib/python3.10/site-packages/requests/api.py", line 59, in request
    return session.request(method=method, url=url, **kwargs)
  File "/home/donkami/.local/lib/python3.10/site-packages/requests/sessions.py", line 589, in request
    resp = self.send(prep, **send_kwargs)
  File "/home/donkami/.local/lib/python3.10/site-packages/requests/sessions.py", line 703, in send
    r = adapter.send(request, **kwargs)
  File "/home/donkami/.local/lib/python3.10/site-packages/requests/adapters.py", line 507, in send
    raise ConnectTimeout(e, request=request)
requests.exceptions.ConnectTimeout: HTTPSConnectionPool(host='10.224.241.25', port=443): Max retries exceeded with url: /api/table.json?content=devices&columns=objid&filter_host=10.224.127.1&username=canadmin&password=Carrera01&count=* (Caused by ConnectTimeoutError(<urllib3.connection.HTTPSConnection object at 0x7f88f26919f0>, 'Connection to 10.224.241.25 timed out. (connect timeout=None)'))

2024-08-21 21:23:28,386 - ERROR - Traceback (most recent call last):
  File "/home/donkami/.local/lib/python3.10/site-packages/urllib3/connection.py", line 200, in _new_conn
    sock = connection.create_connection(
  File "/home/donkami/.local/lib/python3.10/site-packages/urllib3/util/connection.py", line 85, in create_connection
    raise err
  File "/home/donkami/.local/lib/python3.10/site-packages/urllib3/util/connection.py", line 73, in create_connection
    sock.connect(sa)
TimeoutError: [Errno 110] Connection timed out

The above exception was the direct cause of the following exception:

Traceback (most recent call last):
  File "/home/donkami/.local/lib/python3.10/site-packages/urllib3/connectionpool.py", line 790, in urlopen
    response = self._make_request(
  File "/home/donkami/.local/lib/python3.10/site-packages/urllib3/connectionpool.py", line 491, in _make_request
    raise new_e
  File "/home/donkami/.local/lib/python3.10/site-packages/urllib3/connectionpool.py", line 467, in _make_request
    self._validate_conn(conn)
  File "/home/donkami/.local/lib/python3.10/site-packages/urllib3/connectionpool.py", line 1092, in _validate_conn
    conn.connect()
  File "/home/donkami/.local/lib/python3.10/site-packages/urllib3/connection.py", line 604, in connect
    self.sock = sock = self._new_conn()
  File "/home/donkami/.local/lib/python3.10/site-packages/urllib3/connection.py", line 209, in _new_conn
    raise ConnectTimeoutError(
urllib3.exceptions.ConnectTimeoutError: (<urllib3.connection.HTTPSConnection object at 0x7f88f26919f0>, 'Connection to 10.224.241.25 timed out. (connect timeout=None)')

The above exception was the direct cause of the following exception:

Traceback (most recent call last):
  File "/home/donkami/.local/lib/python3.10/site-packages/requests/adapters.py", line 486, in send
    resp = conn.urlopen(
  File "/home/donkami/.local/lib/python3.10/site-packages/urllib3/connectionpool.py", line 844, in urlopen
    retries = retries.increment(
  File "/home/donkami/.local/lib/python3.10/site-packages/urllib3/util/retry.py", line 515, in increment
    raise MaxRetryError(_pool, url, reason) from reason  # type: ignore[arg-type]
urllib3.exceptions.MaxRetryError: HTTPSConnectionPool(host='10.224.241.25', port=443): Max retries exceeded with url: /api/table.json?content=devices&columns=objid&filter_host=10.224.127.1&username=canadmin&password=Carrera01&count=* (Caused by ConnectTimeoutError(<urllib3.connection.HTTPSConnection object at 0x7f88f26919f0>, 'Connection to 10.224.241.25 timed out. (connect timeout=None)'))

During handling of the above exception, another exception occurred:

Traceback (most recent call last):
  File "/home/donkami/Sona/devnet-candelaria/Services/InfraGeneral/main.py", line 87, in core1
    id_prtg_switch = get_id_prtg(ip_switch)
  File "/home/donkami/Sona/devnet-candelaria/Services/InfraGeneral/main.py", line 248, in get_id_prtg
    response_objid = requests.get(url_objid, verify=False).json()
  File "/home/donkami/.local/lib/python3.10/site-packages/requests/api.py", line 73, in get
    return request("get", url, params=params, **kwargs)
  File "/home/donkami/.local/lib/python3.10/site-packages/requests/api.py", line 59, in request
    return session.request(method=method, url=url, **kwargs)
  File "/home/donkami/.local/lib/python3.10/site-packages/requests/sessions.py", line 589, in request
    resp = self.send(prep, **send_kwargs)
  File "/home/donkami/.local/lib/python3.10/site-packages/requests/sessions.py", line 703, in send
    r = adapter.send(request, **kwargs)
  File "/home/donkami/.local/lib/python3.10/site-packages/requests/adapters.py", line 507, in send
    raise ConnectTimeout(e, request=request)
requests.exceptions.ConnectTimeout: HTTPSConnectionPool(host='10.224.241.25', port=443): Max retries exceeded with url: /api/table.json?content=devices&columns=objid&filter_host=10.224.127.1&username=canadmin&password=Carrera01&count=* (Caused by ConnectTimeoutError(<urllib3.connection.HTTPSConnection object at 0x7f88f26919f0>, 'Connection to 10.224.241.25 timed out. (connect timeout=None)'))

2024-08-21 21:23:28,386 - ERROR - Traceback (most recent call last):
  File "/home/donkami/.local/lib/python3.10/site-packages/urllib3/connection.py", line 200, in _new_conn
    sock = connection.create_connection(
  File "/home/donkami/.local/lib/python3.10/site-packages/urllib3/util/connection.py", line 85, in create_connection
    raise err
  File "/home/donkami/.local/lib/python3.10/site-packages/urllib3/util/connection.py", line 73, in create_connection
    sock.connect(sa)
TimeoutError: [Errno 110] Connection timed out

The above exception was the direct cause of the following exception:

Traceback (most recent call last):
  File "/home/donkami/.local/lib/python3.10/site-packages/urllib3/connectionpool.py", line 790, in urlopen
    response = self._make_request(
  File "/home/donkami/.local/lib/python3.10/site-packages/urllib3/connectionpool.py", line 491, in _make_request
    raise new_e
  File "/home/donkami/.local/lib/python3.10/site-packages/urllib3/connectionpool.py", line 467, in _make_request
    self._validate_conn(conn)
  File "/home/donkami/.local/lib/python3.10/site-packages/urllib3/connectionpool.py", line 1092, in _validate_conn
    conn.connect()
  File "/home/donkami/.local/lib/python3.10/site-packages/urllib3/connection.py", line 604, in connect
    self.sock = sock = self._new_conn()
  File "/home/donkami/.local/lib/python3.10/site-packages/urllib3/connection.py", line 209, in _new_conn
    raise ConnectTimeoutError(
urllib3.exceptions.ConnectTimeoutError: (<urllib3.connection.HTTPSConnection object at 0x7f88f26919f0>, 'Connection to 10.224.241.25 timed out. (connect timeout=None)')

The above exception was the direct cause of the following exception:

Traceback (most recent call last):
  File "/home/donkami/.local/lib/python3.10/site-packages/requests/adapters.py", line 486, in send
    resp = conn.urlopen(
  File "/home/donkami/.local/lib/python3.10/site-packages/urllib3/connectionpool.py", line 844, in urlopen
    retries = retries.increment(
  File "/home/donkami/.local/lib/python3.10/site-packages/urllib3/util/retry.py", line 515, in increment
    raise MaxRetryError(_pool, url, reason) from reason  # type: ignore[arg-type]
urllib3.exceptions.MaxRetryError: HTTPSConnectionPool(host='10.224.241.25', port=443): Max retries exceeded with url: /api/table.json?content=devices&columns=objid&filter_host=10.224.127.1&username=canadmin&password=Carrera01&count=* (Caused by ConnectTimeoutError(<urllib3.connection.HTTPSConnection object at 0x7f88f26919f0>, 'Connection to 10.224.241.25 timed out. (connect timeout=None)'))

During handling of the above exception, another exception occurred:

Traceback (most recent call last):
  File "/home/donkami/Sona/devnet-candelaria/Services/InfraGeneral/main.py", line 87, in core1
    id_prtg_switch = get_id_prtg(ip_switch)
  File "/home/donkami/Sona/devnet-candelaria/Services/InfraGeneral/main.py", line 248, in get_id_prtg
    response_objid = requests.get(url_objid, verify=False).json()
  File "/home/donkami/.local/lib/python3.10/site-packages/requests/api.py", line 73, in get
    return request("get", url, params=params, **kwargs)
  File "/home/donkami/.local/lib/python3.10/site-packages/requests/api.py", line 59, in request
    return session.request(method=method, url=url, **kwargs)
  File "/home/donkami/.local/lib/python3.10/site-packages/requests/sessions.py", line 589, in request
    resp = self.send(prep, **send_kwargs)
  File "/home/donkami/.local/lib/python3.10/site-packages/requests/sessions.py", line 703, in send
    r = adapter.send(request, **kwargs)
  File "/home/donkami/.local/lib/python3.10/site-packages/requests/adapters.py", line 507, in send
    raise ConnectTimeout(e, request=request)
requests.exceptions.ConnectTimeout: HTTPSConnectionPool(host='10.224.241.25', port=443): Max retries exceeded with url: /api/table.json?content=devices&columns=objid&filter_host=10.224.127.1&username=canadmin&password=Carrera01&count=* (Caused by ConnectTimeoutError(<urllib3.connection.HTTPSConnection object at 0x7f88f26919f0>, 'Connection to 10.224.241.25 timed out. (connect timeout=None)'))

2024-08-21 21:23:28,386 - ERROR - Traceback (most recent call last):
  File "/home/donkami/.local/lib/python3.10/site-packages/urllib3/connection.py", line 200, in _new_conn
    sock = connection.create_connection(
  File "/home/donkami/.local/lib/python3.10/site-packages/urllib3/util/connection.py", line 85, in create_connection
    raise err
  File "/home/donkami/.local/lib/python3.10/site-packages/urllib3/util/connection.py", line 73, in create_connection
    sock.connect(sa)
TimeoutError: [Errno 110] Connection timed out

The above exception was the direct cause of the following exception:

Traceback (most recent call last):
  File "/home/donkami/.local/lib/python3.10/site-packages/urllib3/connectionpool.py", line 790, in urlopen
    response = self._make_request(
  File "/home/donkami/.local/lib/python3.10/site-packages/urllib3/connectionpool.py", line 491, in _make_request
    raise new_e
  File "/home/donkami/.local/lib/python3.10/site-packages/urllib3/connectionpool.py", line 467, in _make_request
    self._validate_conn(conn)
  File "/home/donkami/.local/lib/python3.10/site-packages/urllib3/connectionpool.py", line 1092, in _validate_conn
    conn.connect()
  File "/home/donkami/.local/lib/python3.10/site-packages/urllib3/connection.py", line 604, in connect
    self.sock = sock = self._new_conn()
  File "/home/donkami/.local/lib/python3.10/site-packages/urllib3/connection.py", line 209, in _new_conn
    raise ConnectTimeoutError(
urllib3.exceptions.ConnectTimeoutError: (<urllib3.connection.HTTPSConnection object at 0x7f88f26919f0>, 'Connection to 10.224.241.25 timed out. (connect timeout=None)')

The above exception was the direct cause of the following exception:

Traceback (most recent call last):
  File "/home/donkami/.local/lib/python3.10/site-packages/requests/adapters.py", line 486, in send
    resp = conn.urlopen(
  File "/home/donkami/.local/lib/python3.10/site-packages/urllib3/connectionpool.py", line 844, in urlopen
    retries = retries.increment(
  File "/home/donkami/.local/lib/python3.10/site-packages/urllib3/util/retry.py", line 515, in increment
    raise MaxRetryError(_pool, url, reason) from reason  # type: ignore[arg-type]
urllib3.exceptions.MaxRetryError: HTTPSConnectionPool(host='10.224.241.25', port=443): Max retries exceeded with url: /api/table.json?content=devices&columns=objid&filter_host=10.224.127.1&username=canadmin&password=Carrera01&count=* (Caused by ConnectTimeoutError(<urllib3.connection.HTTPSConnection object at 0x7f88f26919f0>, 'Connection to 10.224.241.25 timed out. (connect timeout=None)'))

During handling of the above exception, another exception occurred:

Traceback (most recent call last):
  File "/home/donkami/Sona/devnet-candelaria/Services/InfraGeneral/main.py", line 87, in core1
    id_prtg_switch = get_id_prtg(ip_switch)
  File "/home/donkami/Sona/devnet-candelaria/Services/InfraGeneral/main.py", line 248, in get_id_prtg
    response_objid = requests.get(url_objid, verify=False).json()
  File "/home/donkami/.local/lib/python3.10/site-packages/requests/api.py", line 73, in get
    return request("get", url, params=params, **kwargs)
  File "/home/donkami/.local/lib/python3.10/site-packages/requests/api.py", line 59, in request
    return session.request(method=method, url=url, **kwargs)
  File "/home/donkami/.local/lib/python3.10/site-packages/requests/sessions.py", line 589, in request
    resp = self.send(prep, **send_kwargs)
  File "/home/donkami/.local/lib/python3.10/site-packages/requests/sessions.py", line 703, in send
    r = adapter.send(request, **kwargs)
  File "/home/donkami/.local/lib/python3.10/site-packages/requests/adapters.py", line 507, in send
    raise ConnectTimeout(e, request=request)
requests.exceptions.ConnectTimeout: HTTPSConnectionPool(host='10.224.241.25', port=443): Max retries exceeded with url: /api/table.json?content=devices&columns=objid&filter_host=10.224.127.1&username=canadmin&password=Carrera01&count=* (Caused by ConnectTimeoutError(<urllib3.connection.HTTPSConnection object at 0x7f88f26919f0>, 'Connection to 10.224.241.25 timed out. (connect timeout=None)'))

2024-08-21 21:23:28,386 - ERROR - Traceback (most recent call last):
  File "/home/donkami/.local/lib/python3.10/site-packages/urllib3/connection.py", line 200, in _new_conn
    sock = connection.create_connection(
  File "/home/donkami/.local/lib/python3.10/site-packages/urllib3/util/connection.py", line 85, in create_connection
    raise err
  File "/home/donkami/.local/lib/python3.10/site-packages/urllib3/util/connection.py", line 73, in create_connection
    sock.connect(sa)
TimeoutError: [Errno 110] Connection timed out

The above exception was the direct cause of the following exception:

Traceback (most recent call last):
  File "/home/donkami/.local/lib/python3.10/site-packages/urllib3/connectionpool.py", line 790, in urlopen
    response = self._make_request(
  File "/home/donkami/.local/lib/python3.10/site-packages/urllib3/connectionpool.py", line 491, in _make_request
    raise new_e
  File "/home/donkami/.local/lib/python3.10/site-packages/urllib3/connectionpool.py", line 467, in _make_request
    self._validate_conn(conn)
  File "/home/donkami/.local/lib/python3.10/site-packages/urllib3/connectionpool.py", line 1092, in _validate_conn
    conn.connect()
  File "/home/donkami/.local/lib/python3.10/site-packages/urllib3/connection.py", line 604, in connect
    self.sock = sock = self._new_conn()
  File "/home/donkami/.local/lib/python3.10/site-packages/urllib3/connection.py", line 209, in _new_conn
    raise ConnectTimeoutError(
urllib3.exceptions.ConnectTimeoutError: (<urllib3.connection.HTTPSConnection object at 0x7f88f26919f0>, 'Connection to 10.224.241.25 timed out. (connect timeout=None)')

The above exception was the direct cause of the following exception:

Traceback (most recent call last):
  File "/home/donkami/.local/lib/python3.10/site-packages/requests/adapters.py", line 486, in send
    resp = conn.urlopen(
  File "/home/donkami/.local/lib/python3.10/site-packages/urllib3/connectionpool.py", line 844, in urlopen
    retries = retries.increment(
  File "/home/donkami/.local/lib/python3.10/site-packages/urllib3/util/retry.py", line 515, in increment
    raise MaxRetryError(_pool, url, reason) from reason  # type: ignore[arg-type]
urllib3.exceptions.MaxRetryError: HTTPSConnectionPool(host='10.224.241.25', port=443): Max retries exceeded with url: /api/table.json?content=devices&columns=objid&filter_host=10.224.127.1&username=canadmin&password=Carrera01&count=* (Caused by ConnectTimeoutError(<urllib3.connection.HTTPSConnection object at 0x7f88f26919f0>, 'Connection to 10.224.241.25 timed out. (connect timeout=None)'))

During handling of the above exception, another exception occurred:

Traceback (most recent call last):
  File "/home/donkami/Sona/devnet-candelaria/Services/InfraGeneral/main.py", line 87, in core1
    id_prtg_switch = get_id_prtg(ip_switch)
  File "/home/donkami/Sona/devnet-candelaria/Services/InfraGeneral/main.py", line 248, in get_id_prtg
    response_objid = requests.get(url_objid, verify=False).json()
  File "/home/donkami/.local/lib/python3.10/site-packages/requests/api.py", line 73, in get
    return request("get", url, params=params, **kwargs)
  File "/home/donkami/.local/lib/python3.10/site-packages/requests/api.py", line 59, in request
    return session.request(method=method, url=url, **kwargs)
  File "/home/donkami/.local/lib/python3.10/site-packages/requests/sessions.py", line 589, in request
    resp = self.send(prep, **send_kwargs)
  File "/home/donkami/.local/lib/python3.10/site-packages/requests/sessions.py", line 703, in send
    r = adapter.send(request, **kwargs)
  File "/home/donkami/.local/lib/python3.10/site-packages/requests/adapters.py", line 507, in send
    raise ConnectTimeout(e, request=request)
requests.exceptions.ConnectTimeout: HTTPSConnectionPool(host='10.224.241.25', port=443): Max retries exceeded with url: /api/table.json?content=devices&columns=objid&filter_host=10.224.127.1&username=canadmin&password=Carrera01&count=* (Caused by ConnectTimeoutError(<urllib3.connection.HTTPSConnection object at 0x7f88f26919f0>, 'Connection to 10.224.241.25 timed out. (connect timeout=None)'))

2024-08-21 21:23:28,386 - ERROR - Traceback (most recent call last):
  File "/home/donkami/.local/lib/python3.10/site-packages/urllib3/connection.py", line 200, in _new_conn
    sock = connection.create_connection(
  File "/home/donkami/.local/lib/python3.10/site-packages/urllib3/util/connection.py", line 85, in create_connection
    raise err
  File "/home/donkami/.local/lib/python3.10/site-packages/urllib3/util/connection.py", line 73, in create_connection
    sock.connect(sa)
TimeoutError: [Errno 110] Connection timed out

The above exception was the direct cause of the following exception:

Traceback (most recent call last):
  File "/home/donkami/.local/lib/python3.10/site-packages/urllib3/connectionpool.py", line 790, in urlopen
    response = self._make_request(
  File "/home/donkami/.local/lib/python3.10/site-packages/urllib3/connectionpool.py", line 491, in _make_request
    raise new_e
  File "/home/donkami/.local/lib/python3.10/site-packages/urllib3/connectionpool.py", line 467, in _make_request
    self._validate_conn(conn)
  File "/home/donkami/.local/lib/python3.10/site-packages/urllib3/connectionpool.py", line 1092, in _validate_conn
    conn.connect()
  File "/home/donkami/.local/lib/python3.10/site-packages/urllib3/connection.py", line 604, in connect
    self.sock = sock = self._new_conn()
  File "/home/donkami/.local/lib/python3.10/site-packages/urllib3/connection.py", line 209, in _new_conn
    raise ConnectTimeoutError(
urllib3.exceptions.ConnectTimeoutError: (<urllib3.connection.HTTPSConnection object at 0x7f88f26919f0>, 'Connection to 10.224.241.25 timed out. (connect timeout=None)')

The above exception was the direct cause of the following exception:

Traceback (most recent call last):
  File "/home/donkami/.local/lib/python3.10/site-packages/requests/adapters.py", line 486, in send
    resp = conn.urlopen(
  File "/home/donkami/.local/lib/python3.10/site-packages/urllib3/connectionpool.py", line 844, in urlopen
    retries = retries.increment(
  File "/home/donkami/.local/lib/python3.10/site-packages/urllib3/util/retry.py", line 515, in increment
    raise MaxRetryError(_pool, url, reason) from reason  # type: ignore[arg-type]
urllib3.exceptions.MaxRetryError: HTTPSConnectionPool(host='10.224.241.25', port=443): Max retries exceeded with url: /api/table.json?content=devices&columns=objid&filter_host=10.224.127.1&username=canadmin&password=Carrera01&count=* (Caused by ConnectTimeoutError(<urllib3.connection.HTTPSConnection object at 0x7f88f26919f0>, 'Connection to 10.224.241.25 timed out. (connect timeout=None)'))

During handling of the above exception, another exception occurred:

Traceback (most recent call last):
  File "/home/donkami/Sona/devnet-candelaria/Services/InfraGeneral/main.py", line 87, in core1
    id_prtg_switch = get_id_prtg(ip_switch)
  File "/home/donkami/Sona/devnet-candelaria/Services/InfraGeneral/main.py", line 248, in get_id_prtg
    response_objid = requests.get(url_objid, verify=False).json()
  File "/home/donkami/.local/lib/python3.10/site-packages/requests/api.py", line 73, in get
    return request("get", url, params=params, **kwargs)
  File "/home/donkami/.local/lib/python3.10/site-packages/requests/api.py", line 59, in request
    return session.request(method=method, url=url, **kwargs)
  File "/home/donkami/.local/lib/python3.10/site-packages/requests/sessions.py", line 589, in request
    resp = self.send(prep, **send_kwargs)
  File "/home/donkami/.local/lib/python3.10/site-packages/requests/sessions.py", line 703, in send
    r = adapter.send(request, **kwargs)
  File "/home/donkami/.local/lib/python3.10/site-packages/requests/adapters.py", line 507, in send
    raise ConnectTimeout(e, request=request)
requests.exceptions.ConnectTimeout: HTTPSConnectionPool(host='10.224.241.25', port=443): Max retries exceeded with url: /api/table.json?content=devices&columns=objid&filter_host=10.224.127.1&username=canadmin&password=Carrera01&count=* (Caused by ConnectTimeoutError(<urllib3.connection.HTTPSConnection object at 0x7f88f26919f0>, 'Connection to 10.224.241.25 timed out. (connect timeout=None)'))

Traceback (most recent call last):
  File "/home/donkami/.local/lib/python3.10/site-packages/mysql/connector/connection_cext.py", line 291, in _open_connection
    self._cmysql.connect(**cnx_kwargs)
_mysql_connector.MySQLInterfaceError: Access denied for user 'donkami'@'172.18.0.1' (using password: NO)

The above exception was the direct cause of the following exception:

Traceback (most recent call last):
  File "/home/donkami/Sona/devnet-candelaria/Services/Anillo_Ug/db_connection.py", line 21, in devnet_connection
    db_connector = mysql.connector.connect(
  File "/home/donkami/.local/lib/python3.10/site-packages/mysql/connector/pooling.py", line 293, in connect
    return CMySQLConnection(*args, **kwargs)
  File "/home/donkami/.local/lib/python3.10/site-packages/mysql/connector/connection_cext.py", line 120, in __init__
    self.connect(**kwargs)
  File "/home/donkami/.local/lib/python3.10/site-packages/mysql/connector/abstracts.py", line 1181, in connect
    self._open_connection()
  File "/home/donkami/.local/lib/python3.10/site-packages/mysql/connector/connection_cext.py", line 296, in _open_connection
    raise get_mysql_exception(
mysql.connector.errors.ProgrammingError: 1045 (28000): Access denied for user 'donkami'@'172.18.0.1' (using password: NO)

Error en la funci√≥n `devnet_connection` en el archivo `db_connections`
1045 (28000): Access denied for user 'donkami'@'172.18.0.1' (using password: NO)
No se pudo establecer la conexi√≥n con la base de datos: el conector es None.
Traceback (most recent call last):
  File "/home/donkami/Sona/devnet-candelaria/Services/Anillo_Ug/get_data.py", line 31, in get_data
    raise ValueError("No se pudo establecer la conexi√≥n con la base de datos: el conector es None.")
ValueError: No se pudo establecer la conexi√≥n con la base de datos: el conector es None.

Error al obtener datos de la base de datos
Error en la funcion `get_data` en el archivo `get_data`
Traceback (most recent call last):
  File "/home/donkami/.local/lib/python3.10/site-packages/mysql/connector/connection_cext.py", line 291, in _open_connection
    self._cmysql.connect(**cnx_kwargs)
_mysql_connector.MySQLInterfaceError: Access denied for user 'donkami'@'172.18.0.1' (using password: NO)

The above exception was the direct cause of the following exception:

Traceback (most recent call last):
  File "/home/donkami/Sona/devnet-candelaria/Services/Anillo_Ug/db_connection.py", line 21, in devnet_connection
    db_connector = mysql.connector.connect(
  File "/home/donkami/.local/lib/python3.10/site-packages/mysql/connector/pooling.py", line 293, in connect
    return CMySQLConnection(*args, **kwargs)
  File "/home/donkami/.local/lib/python3.10/site-packages/mysql/connector/connection_cext.py", line 120, in __init__
    self.connect(**kwargs)
  File "/home/donkami/.local/lib/python3.10/site-packages/mysql/connector/abstracts.py", line 1181, in connect
    self._open_connection()
  File "/home/donkami/.local/lib/python3.10/site-packages/mysql/connector/connection_cext.py", line 296, in _open_connection
    raise get_mysql_exception(
mysql.connector.errors.ProgrammingError: 1045 (28000): Access denied for user 'donkami'@'172.18.0.1' (using password: NO)

Error en la funci√≥n `devnet_connection` en el archivo `db_connections`
1045 (28000): Access denied for user 'donkami'@'172.18.0.1' (using password: NO)
No se pudo establecer la conexi√≥n con la base de datos: el conector es None.
Traceback (most recent call last):
  File "/home/donkami/Sona/devnet-candelaria/Services/Anillo_Ug/get_devnet_data.py", line 31, in get_data
    raise ValueError("No se pudo establecer la conexi√≥n con la base de datos: el conector es None.")
ValueError: No se pudo establecer la conexi√≥n con la base de datos: el conector es None.

Error al obtener datos de la base de datos
Error en la funcion `get_data` en el archivo `get_data`
Traceback (most recent call last):
  File "/home/donkami/Sona/devnet-candelaria/Services/Anillo_Ug/db_update.py", line 35, in update_devnet_data
    devnet_cursor.executemany(query, data_tuple)
  File "/home/donkami/.local/lib/python3.10/site-packages/mysql/connector/cursor_cext.py", line 465, in executemany
    self.execute(operation, params)
  File "/home/donkami/.local/lib/python3.10/site-packages/mysql/connector/cursor_cext.py", line 323, in execute
    stmt = RE_PY_PARAM.sub(psub, stmt)
  File "/home/donkami/.local/lib/python3.10/site-packages/mysql/connector/cursor_cext.py", line 112, in __call__
    raise ProgrammingError(
mysql.connector.errors.ProgrammingError: Not enough parameters for the SQL statement

Error en la funci√≥n `update_devnet_data` en el archivo `db_update_devnet`
Not enough parameters for the SQL statement
Traceback (most recent call last):
  File "/home/donkami/Sona/devnet-candelaria/Services/Anillo_Ug/db_update.py", line 36, in update_devnet_data
    devnet_cursor.executemany(query, data_tuple)
  File "/home/donkami/.local/lib/python3.10/site-packages/mysql/connector/cursor_cext.py", line 465, in executemany
    self.execute(operation, params)
  File "/home/donkami/.local/lib/python3.10/site-packages/mysql/connector/cursor_cext.py", line 323, in execute
    stmt = RE_PY_PARAM.sub(psub, stmt)
  File "/home/donkami/.local/lib/python3.10/site-packages/mysql/connector/cursor_cext.py", line 112, in __call__
    raise ProgrammingError(
mysql.connector.errors.ProgrammingError: Not enough parameters for the SQL statement

Error en la funci√≥n `update_devnet_data` en el archivo `db_update_devnet`
Not enough parameters for the SQL statement
