2024-02-02 14:05:30,461 - ERROR - Traceback (most recent call last):
  File "/home/donkami/.local/lib/python3.10/site-packages/mysql/connector/connection_cext.py", line 611, in cmd_query
    self._cmysql.query(
_mysql_connector.MySQLInterfaceError: Incorrect integer value: 'None' for column 'cctv_enabled' at row 1

The above exception was the direct cause of the following exception:

Traceback (most recent call last):
  File "/home/donkami/Sona/devnet-candelaria/Services/Camaras/main.py", line 104, in get_devices_data
    cursor.execute(query)
  File "/home/donkami/.local/lib/python3.10/site-packages/mysql/connector/cursor_cext.py", line 330, in execute
    result = self._cnx.cmd_query(
  File "/home/donkami/.local/lib/python3.10/site-packages/mysql/connector/connection_cext.py", line 619, in cmd_query
    raise get_mysql_exception(
mysql.connector.errors.DatabaseError: 1366 (HY000): Incorrect integer value: 'None' for column 'cctv_enabled' at row 1

2024-02-02 14:05:30,461 - ERROR - 10.231.0.15
